Workbook

Sheet QUADRO RESUMO
A1: CLIENTE | B1: CLASSIFICAÇÃO | C1: VALOR MENSAL | D1: SALDO EM ABERTO | E1: OBSERVAÇÕES GERAIS | F1: PLANO DE AÇÃO | G1: RESPONSÁVEL
A2: 3TM | B2: GRAU B | C2: 5100 | D2: ='3TM'!G8 -> 17400 | E2: Acordo em atraso (parcela 30/01 prevista para 13/02). 10 parcelas de R$ 1.730,00, mas está pagando R$ 1.950,00 e o vencimento do mês. | F2: Aguardar prazo 13/02 e financeiro retornar com atualizações. | G2: GIAN
A3: ABG CORPORATE | B3: GRAU B | C3: 17964.07 | D3: =ABG!F6 -> 53892.21 | E3: Cliente parou de retornar. Vencimento dezembro/2025 está na RJ. Advogado que acompanha o caso é o único que responde, mas sem informações concretas. | F3: Verificar com Guerini quem é o financeiro, entrar em contato e trazer retorno sobre o pagamento na próxima reunião. Tentar contato novamente hoje (11/02). | G3: LEONARDO
A4: AMERICAR | B4: GRAU C | C4: 16000 | D4: =AMERICAR!F31 -> 90000 | E4: Disse que os pagamentos serão retomados em fevereiro. | F4: Cada área atualizar sua base. Verificar contato, informar que são 6 semanas desde o último pagamento. Fazer proposta de pagamento em 6 parcelas (chegar no máximo a 10). Prazo cliente até 13/02. Contato até amanhã (06/02). Pagamento de 5k semanal será retomado a partir de 13/02. Valor passado: 30k dia 13/02 + 6 parcelas 10k a partir de 13/03. | G4: RENATO
A5: BILATERAL | B5: GRAU B | C5: 8000 | D5: =BILATERAL!F5 -> 12000 | E5: Fez pagamentos semanais em janeiro e pretende manter o mesmo formato em fevereiro e pagar a do mês. | F5: Aguardar prazo 06/02 e financeiro retornar com atualizações na próxima reunião. Pagamento semana 06/02 ok, acompanhar próximo até 13/02. | G5: JORGE
A6: CDA | B6: GRAU C | C6: 45467.06 | D6: 92728.77 | E6: Bruno sugeriu que o Gustavo entre em contato com Ali. Financeiro do cliente não tem atualizações. Estamos retendo valores de acordos para abatimento. | F6: Formalizar sobre valor retido. Gustavo entrar em contato com Ali. Enviar movimento completo e corrigido hoje. Prazo contato cliente, amanhã (06/02). A partir da próxima semana (16/02) começa a regularizar o mensal. | G6: LEONARDO
A7: CRISTAL & CORES | B7: GRAU B | C7: 18000 | D7: =CRISTAL!F6 -> 44000 | E7: Aguardando envio de programação de pagamentos semanais. | F7: Fazer proposta de parcelamento semanal do atrasado para regularização no prazo máximo de 3 meses (término em abril). Atualizar valor. Tentar contato novamente hoje (11/02) e atualizar status. | G7: JORGE
A8: DMP | B8: GRAU B | C8: 25000 | D8: =DMP!F9 -> 81000 | E8: Dificuldade no retorno, se responde, não informa programação. | F8: Entrar em contato com Daniela, propor pagamento corrente em dia nos próximos 6 meses e regularização do passado com desconto de 50% em 8x (forma de compensação do contrato atual, que está com valor acima). Feito no dia 06/02, aguardando retorno. Entrar em contato novamente hoje (11/02) e agendar reunião. | G8: JORGE
A9: DISEP | B9: GRAU C | C9: 25000 | D9: =DISEP!F6 -> 55000 | E9: Programação saldo final até dia 05/02. | F9: Acompanhar recebimento em 05/02. Enviar pendências para Gustavo, que vai propor pagamento dos 30k restantes (se ele fizer os 25k hoje) até o final de fevereiro. Não fez em 05/02. Programação de 30k até final do mês. | G9: GUSTAVO
A10: FAVIFER | B10: GRAU C | C10: 23300 | D10: =FAVIFER!F46 -> 168100 | E10: Aguardando atualização Wanessa. Guilherme parou de responder. Pagou 2k semana passada. | F10: Entrar em contato com Wanessa, verificar qual a proposta. Fez contato com Paulo, ainda sem retorno da proposta. Tentar contato novamente hoje (11/02). | G10: JORGE
A11: FELICITA | B11: GRAU C | C11: 15000 | D11: =FELICITA!F31 -> 83000 | E11: Aguardando atualização Wanessa. Pagou 6k semana passada. | F11: Entrar em contato com Wanessa, verificar qual a proposta. Tentar contato novamente hoje (11/02). | G11: JORGE
A12: FERRAMENTARIA GASPEC | B12: GRAU C | C12: 19506.71 | D12: ='FERRAMENTARIA GASPEC'!F14 -> 102616.12 | E12: Sem retorno com programação passada, mas pagou um mês em janeiro e um mês em fevereiro. | F12: Atualizar passado, somar ao % de êxito (ver com Ligia). Propor que na entrada do recurso de maquinário seja pago o valor em aberto. Ligia atualizar hoje (11/02). | G12: FINANCEIRO
A13: FORM BOB | B13: GRAU C | C13: 10000 | D13: ='FORM BOB'!F13 -> 97000 | E13: Sem retorno. | F13: Enviar proposta para Gabriel. | G13: GUSTAVO
A14: GRUPO IBS | B14: GRAU C | C14: 10000 | D14: ='GRUPO IBS'!F16 -> 130000 | E14: Programação pagamento parcial até fim do mês. Não fez e não retorna. | F14: Falar com Dagoberto, ver quanto consegue. Agendar reunião. Manter em standby por enquanto (definição em 11/02). | G14: GUSTAVO
A15: LINOPLAST | B15: GRAU B | C15: 15000 | D15: =LINOPLAST!F5 -> 30000 | E15: Tem feito pelo menos um pagamento por mês. | F15: Fazer proposta para adicionar 3k por mês até zerar os 30k. Cobrar retorno hoje (11/02). | G15: LEONARDO
A16: LIRA | B16: GRAU C | C16: 15000 | D16: =LIRA!F11 -> 110000 | E16: Pagou um mês em janeiro. | F16: Falar com Ligia para propor pagamento até março. Retorna com atualizações hoje (11/02). | G16: GUSTAVO
A17: LIVRARIA CULTURA | B17: GRAU C | C17: 30000 | D17: ='LIVRARIA CULTURA'!F105 -> 209800 | E17: Fez mil reais no fim de janeiro. | F17: Enviar saldo atualizado. Apresentar números e condicionar execução dos trabalhos ao pagamento semanal de 10k. | G17: LEONARDO
A18: LOYAL PROFIT | B18: GRAU C | C18: 3237.02 | D18: =LOYAL!F12 -> 26318.28 | E18: Sem retorno. | F18: Formalizar saldo, propor devolução dos processos e o pagamento do saldo em aberto em 6x. Reunião hoje (11/02) às 10h30. | G18: GUSTAVO
A19: MAZDA | B19: GRAU C | C19: 15648 | D19: =MAZDA!F9 -> 81356.82 | E19: Acordo em andamento. 11 parcelas de R$ 6.606,88 + vencimento do mês. Não pagou janeiro. | F19: Formalizar para colocar em dia. Pagou janeiro e acordo está em andamento. | G19: JORGE
A20: METALCASTY | B20: GRAU C | C20: 52925 | D20: =METALCASTY!F14 -> 240560.5 | E20: Fernanda pediu reunião com o Gustavo, não pagou janeiro. Temos valor de MLE 2k para repasse, podemos reter? | F20: Reunião com Gustavo na terça-feira (10/02). Formalizar qual o valor recebido pela liberação judicial. Retornar com atualizações na próxima semana. | G20: GUSTAVO/LEONARDO
A21: MOVENT | B21: GRAU C | C21: 15000 | D21: =MOVENT!F8 -> 190000 | E21: Gustavo orientou aguardar fevereiro para verificar o passado. Janeiro está pago. | F21: Acompanhar pagamento em fevereiro. Valor em aberto do passado será tratado em março. | G21: LEONARDO
A22: OFFICER/LUCIANO | B22: GRAU C | C22: 26500 | D22: ='OFFICER-LUCIANO'!F34 -> 348421.25 | E22: Luciano disse que está aguardando assinatura de um distrato para ter atualizações. | F22: Falar com Wanessa para manter o mensal em dia. | G22: GUSTAVO
A23: PRISCILLA ROSSETTI | B23: GRAU C | C23: 650 | D23: ='PRISCILLA ROSSETTI'!F12 -> 5850 | E23: Praticamente toda semana diz que vai tentar, mas não faz. | F23: Junto com Officer | G23: GUSTAVO
A24: RCG | B24: GRAU C | C24: 11700 | D24: =RCG!F16 -> 151171.65 | E24: Renúncia? Proposta? | F24: Formalizar proposta enviada até a próxima reunião. Ajustado novo valor mensal, aguardando definição sobre o passado. | G24: LEONARDO
A25: SOLON | B25: GRAU C | D25: 6000 | E25: Entender | G25: GIAN/LEONARDO
A26: SPEL EMBALAGENS | B26: GRAU C | C26: 28000 | D26: =SPEL!F9 -> 114154.84 | E26: Disse que vai pagar em dia (cumpriu janeiro) e envia programação para regularização do passado até dia 10/02. | F26: Verificar se já tem proposta para regularização do passado. | G26: FINANCEIRO
A27: VERSOPLAS/BMR | B27: GRAU C | C27: 18000 | D27: =VERSOPLAS!F10 -> 102195.28 | E27: Enviado relatório de pendências para Wanessa na semana passada. | F27: Entrar em contato com Wanessa, verificar qual a proposta. Tentar contato novamente hoje (11/02). | G27: JORGE
A28: ANTONINI | B28: GRAU B | C28: 2500 | D28: =ANTONINI!F5 -> 5000 | E28: Deixou acumular 3 meses, enviou programações e não cumpriu. Proposta de acordo quinzenal, alinhada com Gian. Pagou primeira no dia 30/01. | F28: Acompanhar próximo pagamento mensal + atrasada que está prevista até o final do mês. | G28: FINANCEIRO
A29: M.M.P. | B29: GRAU A | C29: 28500 | D29: ='M.M.P.'!F5 -> 34750 | E29: Sempre pagou em dia, mas em dezembro atrasou. Fez dois pagamentos em janeiro, ainda para abater em dezembro. Wanessa está tentando ajudar. | G29: JORGE
A30: BEATRIZ BALDO | B30: GRAU B | C30: 2311.4 | D30: ='BEATRIZ BALDO'!F6 -> 6595.4 | E30: Atualmente paga êxito sobre pensão, está em dia, mas tem débitos do passado e não responde o financeiro. Responde o Felipe de vez em quando. | F30: Tentar contato novamente. | G30: FELIPE
A31: ROSI MARY SANTOS | B31: GRAU B | C31: 1000 | D31: ='ROSI MARY'!F5 -> 1500 | E31: Ricardo Ungaro não responde o financeiro. Pagou 1.500,00 dia 04/02. | F31: Está com renúncia em andamento, verificar programação do saldo em aberto + último faturamento. | G31: RENATO
A32: LOREN SID | B32: GRAU A | C32: 22972.4 | D32: ='LOREN SID'!F12 -> 103375.8 | E32: Cliente com redução de 50% de maio até então, precisamos analisar proposta para regualarização do passado em aberto. | F32: Ajustar mensal para 15k primeiro e depois definir sobre a regularização do passado.

Sheet Planilha1
A1: CLIENTE | B1: STATUS | C1: PROVIDENCIA G | D1: DATA P G | E1: FU | F1: DATA UP
A2: 3TM | C2: GUSTAVO VAI FALAR COM GABRIEL | D2: 46065 | E2: VAI ENVIAR UMA PROPOSTA | F2: 46068
A3: 3TM | C3: VERIFICAR PROPOSTA E DELIBERR EM COMITE | D3: 46071

Sheet 3TM
A2: Data Vencimento | B2: Cliente | C2: Descrição | D2: Valor Faturado | E2: Valor Pago | F2: Data PG | G2: Valor em Aberto | H2: Data Baixa
A3: 30/08/2025 | B3: 3Tm Distribuidora de Embalagens Ltda | C3: SERVIÇOS ADVOCATÍCIOS | D3: 5100 | E3: 3000 | G3: 2100 | H3: 00/00/0000
A4: 30/09/2025 | B4: 3Tm Distribuidora de Embalagens Ltda | C4: SERVIÇOS ADVOCATÍCIOS | D4: 5100 | E4: 0 | G4: 5100 | H4: 00/00/0000
A5: 30/10/2025 | B5: 3Tm Distribuidora de Embalagens Ltda | C5: SERVIÇOS ADVOCATÍCIOS | D5: 5100 | E5: 0 | G5: 5100 | H5: 00/00/0000
A6: 46052 | B6: 3Tm Distribuidora de Embalagens Ltda | C6: SERVIÇOS ADVOCATÍCIOS | D6: 5100 | E6: 0 | G6: 5100 | H6: 00/00/0000
G8: =SUM(G3:G6) -> 17400
A13: Acordo em outubro/2025 - 10 parcelas de R$ 1.730,00 + honorário do mês, com primeiro vencimento em novembro/2025

Sheet ABG
A2: Data Vencimento | B2: Cliente | C2: Descrição | D2: Valor Faturado | E2: Valor Pago | F2: Valor em Aberto | G2: Valor Atualizado | H2: Data Baixa
A3: 09/12/2025 | B3: Abg Corporate Ltda | C3: SERVIÇOS ADVOCATÍCIOS | D3: 17964.07 | E3: 0 | F3: 17964.07 | G3: 18405.9 | H3: 00/00/0000
A4: 09/01/2026 | B4: Abg Corporate Ltda | C4: SERVIÇOS ADVOCATÍCIOS | D4: 17964.07 | E4: 0 | F4: 17964.07 | G4: 18180 | H4: 00/00/0000
A5: 46062 | B5: Abg Corporate Ltda | C5: SERVIÇOS ADVOCATÍCIOS | D5: 17964.07 | E5: 0 | F5: =D5 -> 17964.07
F6: =SUM(F3:F5) -> 53892.21 | G6: =SUM(G3:G4) -> 36585.9

Sheet AMERICAR
A2: Data Vencimento | B2: Cliente | C2: Descrição | D2: Valor Faturado | E2: Valor Pago | F2: Valor em Aberto | G2: Valor Atualizado | H2: Data Baixa
A3: 45644 | B3: Americar Equipamentos e Pecas Para Movimentacao de Materiais Ltda | C3: SERVIÇOS ADVOCATÍCIOS | D3: 16000 | E3: 16000 | F3: =D3-E3 -> 0 | G3: 0 | H3: 45685
A4: 18/01/2025 | B4: Americar Equipamentos e Pecas Para Movimentacao de Materiais Ltda | C4: SERVIÇOS ADVOCATÍCIOS | D4: 16000 | E4: 16000 | F4: =D4-E4 -> 0 | G4: 0 | H4: 04/04/2025
A5: 18/02/2025 | B5: Americar Equipamentos e Pecas Para Movimentacao de Materiais Ltda | C5: SERVIÇOS ADVOCATÍCIOS | D5: 16000 | E5: 16000 | F5: =D5-E5 -> 0 | G5: 0 | H5: 24/04/2025
A6: 18/03/2025 | B6: Americar Equipamentos e Pecas Para Movimentacao de Materiais Ltda | C6: SERVIÇOS ADVOCATÍCIOS | D6: 16000 | E6: 16000 | F6: =D6-E6 -> 0 | G6: 0 | H6: 23/05/2025
A7: 18/04/2025 | B7: Americar Equipamentos e Pecas Para Movimentacao de Materiais Ltda | C7: SERVIÇOS ADVOCATÍCIOS | D7: 16000 | E7: 5000 | H7: 29/08/2025
A8: 18/04/2025 | B8: Americar Equipamentos e Pecas Para Movimentacao de Materiais Ltda | C8: SERVIÇOS ADVOCATÍCIOS | E8: 5000 | H8: 05/09/2025
A9: 18/04/2025 | B9: Americar Equipamentos e Pecas Para Movimentacao de Materiais Ltda | C9: SERVIÇOS ADVOCATÍCIOS | E9: 5000 | H9: 22/09/2025
A10: 18/04/2025 | B10: Americar Equipamentos e Pecas Para Movimentacao de Materiais Ltda | C10: SERVIÇOS ADVOCATÍCIOS | E10: 1000 | F10: =D7-SUM(E7:E10) -> 0 | G10: 0 | H10: 25/09/2025
A11: 18/05/2025 | B11: Americar Equipamentos e Pecas Para Movimentacao de Materiais Ltda | C11: SERVIÇOS ADVOCATÍCIOS | D11: 16000 | E11: 4000 | H11: 25/09/2025
A12: 18/05/2025 | B12: Americar Equipamentos e Pecas Para Movimentacao de Materiais Ltda | C12: SERVIÇOS ADVOCATÍCIOS | E12: 5000 | H12: 10/10/2025
A13: 18/05/2025 | B13: Americar Equipamentos e Pecas Para Movimentacao de Materiais Ltda | C13: SERVIÇOS ADVOCATÍCIOS | E13: 5000 | H13: 17/10/2025
A14: 18/05/2025 | B14: Americar Equipamentos e Pecas Para Movimentacao de Materiais Ltda | C14: SERVIÇOS ADVOCATÍCIOS | E14: 2000 | F14: =D11-SUM(E11:E14) -> 0 | G14: 0 | H14: 24/10/2025
A15: 18/06/2025 | B15: Americar Equipamentos e Pecas Para Movimentacao de Materiais Ltda | C15: SERVIÇOS ADVOCATÍCIOS | D15: 16000 | E15: 3000 | H15: 24/10/2025
A16: 18/06/2025 | B16: Americar Equipamentos e Pecas Para Movimentacao de Materiais Ltda | C16: SERVIÇOS ADVOCATÍCIOS | E16: 5000 | H16: 31/10/2025
A17: 18/06/2025 | B17: Americar Equipamentos e Pecas Para Movimentacao de Materiais Ltda | C17: SERVIÇOS ADVOCATÍCIOS | E17: 5000 | H17: 07/11/2025
A18: 18/06/2025 | B18: Americar Equipamentos e Pecas Para Movimentacao de Materiais Ltda | C18: SERVIÇOS ADVOCATÍCIOS | E18: 3000 | F18: =D15-SUM(E15:E18) -> 0 | G18: 0 | H18: 14/11/2025
A19: 18/07/2025 | B19: Americar Equipamentos e Pecas Para Movimentacao de Materiais Ltda | C19: SERVIÇOS ADVOCATÍCIOS | D19: 16000 | E19: 2000 | H19: 14/11/2025
A20: 18/07/2025 | B20: Americar Equipamentos e Pecas Para Movimentacao de Materiais Ltda | C20: SERVIÇOS ADVOCATÍCIOS | E20: 5000 | H20: 27/11/2025
A21: 18/07/2025 | B21: Americar Equipamentos e Pecas Para Movimentacao de Materiais Ltda | C21: SERVIÇOS ADVOCATÍCIOS | E21: 5000 | H21: 28/11/2025 | J21: Valor corrente
A22: 18/07/2025 | B22: Americar Equipamentos e Pecas Para Movimentacao de Materiais Ltda | C22: SERVIÇOS ADVOCATÍCIOS | E22: 4000 | F22: =D19-SUM(E19:E22) -> 0 | G22: 0 | H22: 05/12/2025 | J22: Proposta BP | K22: Retomada dos R$ 5.000 | L22: 46059 | M22: 46065
A23: 18/08/2025 | B23: Americar Equipamentos e Pecas Para Movimentacao de Materiais Ltda | C23: SERVIÇOS ADVOCATÍCIOS | D23: 16000 | E23: 1000 | H23: 05/12/2025 | J23: Contraproposta Americar | K23: 5000 | L23: 46066
A24: 18/08/2025 | B24: Americar Equipamentos e Pecas Para Movimentacao de Materiais Ltda | C24: SERVIÇOS ADVOCATÍCIOS | E24: 5000 | H24: 12/12/2025
A25: 18/08/2025 | B25: Americar Equipamentos e Pecas Para Movimentacao de Materiais Ltda | C25: SERVIÇOS ADVOCATÍCIOS | E25: 0 | F25: =D23-SUM(E23:E25) -> 10000 | G25: 12748.01 | H25: 00/00/0000 | J25: Valor em atrasado
A26: 18/09/2025 | B26: Americar Equipamentos e Pecas Para Movimentacao de Materiais Ltda | C26: SERVIÇOS ADVOCATÍCIOS | D26: 16000 | E26: 0 | F26: 16000 | G26: 20263.31 | H26: 00/00/0000 | K26: Valor | L26: Parcelas | M26: Valor parcelas
A27: 18/10/2025 | B27: Americar Equipamentos e Pecas Para Movimentacao de Materiais Ltda | C27: SERVIÇOS ADVOCATÍCIOS | D27: 16000 | E27: 0 | F27: 16000 | G27: 20005.18 | H27: 00/00/0000 | J27: Proposta BP | K27: 90000 | L27: 6 | M27: =K27/L27 -> 15000
A28: 18/11/2025 | B28: Americar Equipamentos e Pecas Para Movimentacao de Materiais Ltda | C28: SERVIÇOS ADVOCATÍCIOS | D28: 16000 | E28: 0 | F28: 16000 | G28: 19808.19 | H28: 00/00/0000 | J28: Contraproposta Americar | K28: 0 | M28: =K28/L28 -> #DIV/0!
A29: 18/12/2025 | B29: Americar Equipamentos e Pecas Para Movimentacao de Materiais Ltda | C29: SERVIÇOS ADVOCATÍCIOS | D29: 16000 | E29: 0 | F29: 16000 | G29: 19607.94 | H29: 00/00/0000 | J29: Até 13/02 | K29: 30000 | L29: 1 | M29: 30000
A30: 18/01/2026 | B30: Americar Equipamentos e Pecas Para Movimentacao de Materiais Ltda | C30: SERVIÇOS ADVOCATÍCIOS | D30: 16000 | E30: 0 | F30: 16000 | G30: 19398.72 | H30: 00/00/0000 | J30: A partir de 03/2026 | K30: 60000 | L30: 6 | M30: =K30/L30 -> 10000
F31: =SUM(F25:F30) -> 90000 | G31: =SUM(G25:G30) -> 111831.35
J32: Rafael da besten voltará semana que vem > enviar e-mail ao Renato
A33: 45957 | B33: Americar Equipamentos e Pecas Para Movimentacao de Materiais Ltda | C33: REEMBOLSO - AUDIENCIA TRAB. VARA DO TRABALHO DE MOGI MIRIM | D33: 84.04 | E33: 0 | F33: =D33-E33 -> 84.04 | H33: 00/00/0000
A34: 46013 | B34: Americar Equipamentos e Pecas Para Movimentacao de Materiais Ltda | C34: REEMBOLSO - AUDIENCIA TRAB. VARA DO TRABALHO DE MOGI MIRIM | D34: 84.04 | E34: 0 | F34: =D34-E34 -> 84.04 | H34: 00/00/0000
A35: 46021 | B35: Americar Equipamentos e Pecas Para Movimentacao de Materiais Ltda | C35: REEMBOLSO - COMITE SEDE AMERICAR E AUDIENCIA PRESENCIAL EM MOGI MIRIM | D35: 258.52 | E35: 0 | F35: =D35-E35 -> 258.52 | H35: 00/00/0000
E36: Reembolsos | F36: =SUM(F33:F35) -> 426.6

Sheet BILATERAL
A2: Data Vencimento | B2: Cliente | C2: Descrição | D2: Valor Faturado | E2: Valor Pago | F2: Valor em Aberto | G2: Data Baixa
A3: 05/01/2026 | B3: Terral Prime Intermediacoes e Participacoes Em Negocios Ltda | C3: SERVIÇOS ADVOCATÍCIOS | D3: 8000 | E3: 4000 | F3: 4000 | G3: 00/00/0000
A4: 46058 | B4: Terral Prime Intermediacoes e Participacoes Em Negocios Ltda | C4: SERVIÇOS ADVOCATÍCIOS | D4: 8000 | E4: 0 | F4: =D4-E4 -> 8000
F5: =SUM(F3:F4) -> 12000

Sheet CDA
A2: Data Vencimento | B2: Cliente | C2: Descrição | D2: Valor Faturado | E2: Valor Pago | F2: Valor em Aberto | G2: Valor Atualizado | H2: Data Baixa
A3: 15/07/2025 | B3: CDA COMERCIO INDUSTRIA DE METAIS LTDA | C3: SERVIÇOS ADVOCATÍCIOS | D3: 45467.06 | E3: 45467.06 | F3: =D3-E3 -> 0 | G3: 0 | H3: 15/07/2025
A4: 15/08/2025 | B4: CDA COMERCIO INDUSTRIA DE METAIS LTDA | C4: SERVIÇOS ADVOCATÍCIOS | D4: 45467.06 | E4: 45467.06 | F4: =D4-E4 -> 0 | G4: 0 | H4: 26/08/2025
A5: 15/09/2025 | B5: CDA COMERCIO INDUSTRIA DE METAIS LTDA | C5: SERVIÇOS ADVOCATÍCIOS | D5: 45467.06 | E5: 30000 | H5: 23/10/2025
A6: 15/09/2025 | B6: CDA COMERCIO INDUSTRIA DE METAIS LTDA | C6: SERVIÇOS ADVOCATÍCIOS | E6: 346.61 | H6: 20/10/2025 | I6: Valor ref. processo área trabalhista que não foi repassado. Proc. 0002434-69.2016.5.17.0141
A7: 15/09/2025 | B7: CDA COMERCIO INDUSTRIA DE METAIS LTDA | C7: SERVIÇOS ADVOCATÍCIOS | E7: 132.09 | H7: 20/10/2025 | I7: Valor ref. processo área trabalhista que não foi repassado. Proc. 0002434-69.2016.5.17.0141
A8: 15/09/2025 | B8: CDA COMERCIO INDUSTRIA DE METAIS LTDA | C8: SERVIÇOS ADVOCATÍCIOS | E8: 132.98 | H8: 20/10/2025 | I8: Valor ref. processo área trabalhista que não foi repassado. Proc. 0002434-69.2016.5.17.0141
A9: 15/09/2025 | B9: CDA COMERCIO INDUSTRIA DE METAIS LTDA | C9: SERVIÇOS ADVOCATÍCIOS | E9: 133.87 | H9: 20/10/2025 | I9: Valor ref. processo área trabalhista que não foi repassado. Proc. 0002434-69.2016.5.17.0141
A10: 15/09/2025 | B10: CDA COMERCIO INDUSTRIA DE METAIS LTDA | C10: SERVIÇOS ADVOCATÍCIOS | E10: 14721.51 | F10: =D5-SUM(E5:E10) -> 0 | G10: 0 | H10: 05/11/2025 | I10: Valor ref. acordo F.A. da Costa que não foi repassado (Valor total R$ 19.332,45)
A11: 45945 | B11: CDA COMERCIO INDUSTRIA DE METAIS LTDA | C11: SERVIÇOS ADVOCATÍCIOS | D11: 45467.06 | E11: 4610.94 | H11: 05/11/2025 | I11: Valor ref. acordo F.A. da Costa que não foi repassado (Valor total R$ 19.332,45)
A12: 45945 | B12: CDA COMERCIO INDUSTRIA DE METAIS LTDA | C12: SERVIÇOS ADVOCATÍCIOS | E12: 40856.12 | F12: =D11-SUM(E11:E12) -> 0 | G12: 0 | H12: 24/11/2025
A13: 45976 | B13: CDA COMERCIO INDUSTRIA DE METAIS LTDA | C13: SERVIÇOS ADVOCATÍCIOS | D13: 45467.06 | E13: 4610.94 | H13: 24/11/2025
A14: 15/11/2025 | B14: CDA COMERCIO INDUSTRIA DE METAIS LTDA | C14: SERVIÇOS ADVOCATÍCIOS | E14: 132.42 | H14: 02/12/2025 | I14: Valor ref. processo área trabalhista que não foi repassado. Proc. 0002434-69.2016.5.17.0141
A15: 15/11/2025 | B15: CDA COMERCIO INDUSTRIA DE METAIS LTDA | C15: SERVIÇOS ADVOCATÍCIOS | E15: 19332.45 | H15: 05/12/2025 | I15: Valor ref. acordo F.A. da Costa que não foi repassado.
A16: 15/11/2025 | B16: CDA COMERCIO INDUSTRIA DE METAIS LTDA | C16: SERVIÇOS ADVOCATÍCIOS | E16: 131.88 | H16: 12/12/2025 | I16: Valor ref. processo área trabalhista que não foi repassado. Proc. 0002434-69.2016.5.17.0141
A17: 15/11/2025 | B17: CDA COMERCIO INDUSTRIA DE METAIS LTDA | C17: SERVIÇOS ADVOCATÍCIOS | E17: 19332.45 | H17: 26/01/2026 | I17: Valor ref. acordo F.A. da Costa que não foi repassado.
A18: 15/11/2025 | B18: CDA COMERCIO INDUSTRIA DE METAIS LTDA | C18: SERVIÇOS ADVOCATÍCIOS | E18: 132.27 | H18: 26/01/2026 | I18: Valor ref. processo área trabalhista que não foi repassado. Proc. 0002434-69.2016.5.17.0141
A19: 15/11/2025 | B19: CDA COMERCIO INDUSTRIA DE METAIS LTDA | C19: SERVIÇOS ADVOCATÍCIOS | E19: 0 | F19: =D13-SUM(E13:E18) -> 1794.65 | G19: 1860.53 | H19: 00/00/0000
A20: 15/12/2025 | B20: CDA COMERCIO INDUSTRIA DE METAIS LTDA | C20: SERVIÇOS ADVOCATÍCIOS | D20: 45467.06 | E20: 0 | F20: 45467.06 | G20: 46585.33 | H20: 00/00/0000
A21: 15/01/2026 | B21: CDA COMERCIO INDUSTRIA DE METAIS LTDA | C21: SERVIÇOS ADVOCATÍCIOS | D21: 45467.06 | E21: 0 | F21: 45467.06 | G21: 46013.57 | H21: 00/00/0000
F22: =SUM(F19:F21) -> 92728.77 | G22: =SUM(G3:G21) -> 94459.43

Sheet CRISTAL
A2: Data Vencimento | B2: Cliente | C2: Descrição | D2: Valor Faturado | E2: Valor Pago | F2: Valor em Aberto | G2: Valor Atualizado | H2: Data Baixa
A3: 28/11/2025 | B3: Cristal & Cores Chapas Acrilicas Ltda | C3: SERVIÇOS ADVOCATÍCIOS | D3: 18000 | E3: 10000 | F3: 8000 | G3: 9904.09 | H3: 00/00/0000
A4: 28/12/2025 | B4: Cristal & Cores Chapas Acrilicas Ltda | C4: SERVIÇOS ADVOCATÍCIOS | D4: 18000 | E4: 0 | F4: 18000 | G4: 22058.93 | H4: 00/00/0000
A5: 28/01/2026 | B5: Cristal & Cores Chapas Acrilicas Ltda | C5: SERVIÇOS ADVOCATÍCIOS | D5: 18000 | E5: 0 | F5: 18000 | G5: 21823.56 | H5: 00/00/0000
F6: =SUM(F3:F5) -> 44000 | G6: =SUM(G3:G5) -> 53786.58

Sheet DMP
A2: Data Vencimento | B2: Cliente | C2: Descrição | D2: Valor Faturado | E2: Valor Pago | F2: Valor em Aberto | G2: Data Baixa
A3: 30/10/2025 | B3: D.m.p.equipamentos Ltda. | C3: SERVIÇOS ADVOCATÍCIOS | D3: 23000 | E3: 6000 | G3: 46013
A4: 30/10/2025 | B4: D.m.p.equipamentos Ltda. | C4: SERVIÇOS ADVOCATÍCIOS | E4: 7000 | G4: 46048
A5: 30/10/2025 | B5: D.m.p.equipamentos Ltda. | C5: SERVIÇOS ADVOCATÍCIOS | E5: 0 | F5: =D3-SUM(E3:E5) -> 10000 | G5: 00/00/0000
A6: 30/11/2025 | B6: D.m.p.equipamentos Ltda. | C6: SERVIÇOS ADVOCATÍCIOS | D6: 23000 | E6: 0 | F6: 23000 | G6: 00/00/0000
A7: 30/12/2025 | B7: D.m.p.equipamentos Ltda. | C7: SERVIÇOS ADVOCATÍCIOS | D7: 23000 | E7: 0 | F7: 23000 | G7: 00/00/0000
A8: 46052 | B8: D.m.p.equipamentos Ltda. | C8: SERVIÇOS ADVOCATÍCIOS | D8: 25000 | E8: 0 | F8: 25000 | G8: 00/00/0000
F9: =SUM(F3:F8) -> 81000

Sheet DISEP
A2: Data Vencimento | B2: Cliente | C2: Descrição | D2: Valor Faturado | E2: Valor Pago | F2: Valor em Aberto | G2: Valor Atualizado | H2: Data Baixa
A3: 29/11/2025 | B3: Disep Alimentos Ltda | C3: SERVIÇOS ADVOCATÍCIOS | D3: 25000 | E3: 20000 | F3: 5000 | G3: 6190.06 | H3: 00/00/0000
A4: 29/12/2025 | B4: Disep Alimentos Ltda | C4: SERVIÇOS ADVOCATÍCIOS | D4: 25000 | E4: 0 | F4: 25000 | G4: 30637.39 | H4: 00/00/0000
A5: 46051 | B5: Disep Alimentos Ltda | C5: SERVIÇOS ADVOCATÍCIOS | D5: 25000 | E5: 0 | F5: 25000 | G5: 30310.5 | H5: 00/00/0000
F6: =SUM(F3:F5) -> 55000 | G6: =SUM(G3:G5) -> 67137.95

Sheet FAVIFER
A2: Data Vencimento | B2: Cliente | C2: Descrição | D2: Valor Faturado | E2: Valor Pago | F2: Valor em Aberto | G2: Valor Atualizado | H2: Data Baixa
A3: 15/12/2024 | B3: FAVIFER COMERCIO DE FERRO E ACO LTDA | C3: SERVIÇOS ADVOCATÍCIOS | D3: 23300 | E3: 23300 | F3: =D3-E3 -> 0 | G3: 0 | H3: 07/02/2025
A4: 15/01/2025 | B4: FAVIFER COMERCIO DE FERRO E ACO LTDA | C4: SERVIÇOS ADVOCATÍCIOS | D4: 23300 | E4: 11650 | H4: 07/03/2025
A5: 15/01/2025 | B5: FAVIFER COMERCIO DE FERRO E ACO LTDA | C5: SERVIÇOS ADVOCATÍCIOS | E5: 11650 | F5: =D4-E4-E5 -> 0 | G5: 0 | H5: 14/03/2025
A6: 15/02/2025 | B6: FAVIFER COMERCIO DE FERRO E ACO LTDA | C6: SERVIÇOS ADVOCATÍCIOS | D6: 23300 | E6: 11650 | H6: 11/04/2025
A7: 15/02/2025 | B7: FAVIFER COMERCIO DE FERRO E ACO LTDA | C7: SERVIÇOS ADVOCATÍCIOS | E7: 537.5 | H7: 17/10/2025
A8: 15/02/2025 | B8: FAVIFER COMERCIO DE FERRO E ACO LTDA | C8: SERVIÇOS ADVOCATÍCIOS | E8: 537.5 | H8: 24/10/2025
A9: 15/02/2025 | B9: FAVIFER COMERCIO DE FERRO E ACO LTDA | C9: SERVIÇOS ADVOCATÍCIOS | E9: 537.5 | H9: 31/10/2025
A10: 15/02/2025 | B10: FAVIFER COMERCIO DE FERRO E ACO LTDA | C10: SERVIÇOS ADVOCATÍCIOS | E10: 537.5 | H10: 10/11/2025
A11: 15/02/2025 | B11: FAVIFER COMERCIO DE FERRO E ACO LTDA | C11: SERVIÇOS ADVOCATÍCIOS | E11: 537.5 | H11: 14/11/2025
A12: 15/02/2025 | B12: FAVIFER COMERCIO DE FERRO E ACO LTDA | C12: SERVIÇOS ADVOCATÍCIOS | E12: 537.5 | H12: 25/11/2025
A13: 15/02/2025 | B13: FAVIFER COMERCIO DE FERRO E ACO LTDA | C13: SERVIÇOS ADVOCATÍCIOS | E13: 537.5 | H13: 28/11/2025
A14: 15/02/2025 | B14: FAVIFER COMERCIO DE FERRO E ACO LTDA | C14: SERVIÇOS ADVOCATÍCIOS | E14: 537.5 | H14: 19/12/2025
A15: 15/02/2025 | B15: FAVIFER COMERCIO DE FERRO E ACO LTDA | C15: SERVIÇOS ADVOCATÍCIOS | E15: 2000 | F15: =D6-(SUM(E6:E15)) -> 5350 | G15: 7380.1 | H15: 46050
A16: 15/03/2025 | B16: FAVIFER COMERCIO DE FERRO E ACO LTDA | C16: SERVIÇOS ADVOCATÍCIOS | D16: 23300 | E16: 11650 | F16: =D16-E16 -> 11650 | G16: 15755.15 | H16: 29/04/2025
A17: 15/04/2025 | B17: FAVIFER COMERCIO DE FERRO E ACO LTDA | C17: SERVIÇOS ADVOCATÍCIOS | D17: 23300 | E17: 2912.5 | H17: 05/06/2025
A18: 15/04/2025 | B18: FAVIFER COMERCIO DE FERRO E ACO LTDA | C18: SERVIÇOS ADVOCATÍCIOS | E18: 2912.5 | H18: 11/06/2025
A19: 15/04/2025 | B19: FAVIFER COMERCIO DE FERRO E ACO LTDA | C19: SERVIÇOS ADVOCATÍCIOS | E19: 2912.5 | H19: 20/06/2025
A20: 15/04/2025 | B20: FAVIFER COMERCIO DE FERRO E ACO LTDA | C20: SERVIÇOS ADVOCATÍCIOS | E20: 2912.5 | F20: =D17-(SUM(E17:E20)) -> 11650 | G20: 15535.46 | H20: 04/07/2025
A21: 15/05/2025 | B21: FAVIFER COMERCIO DE FERRO E ACO LTDA | C21: SERVIÇOS ADVOCATÍCIOS | D21: 23300 | E21: 2912.5 | H21: 11/07/2025
A22: 15/05/2025 | B22: FAVIFER COMERCIO DE FERRO E ACO LTDA | C22: SERVIÇOS ADVOCATÍCIOS | E22: 2912.5 | H22: 18/07/2025
A23: 15/05/2025 | B23: FAVIFER COMERCIO DE FERRO E ACO LTDA | C23: SERVIÇOS ADVOCATÍCIOS | E23: 2912.5 | H23: 01/08/2025
A24: 15/05/2025 | B24: FAVIFER COMERCIO DE FERRO E ACO LTDA | C24: SERVIÇOS ADVOCATÍCIOS | E24: 2912.5 | F24: =D21-(SUM(E21:E24)) -> 11650 | G24: 15349.95 | H24: 07/08/2025
A25: 15/06/2025 | B25: FAVIFER COMERCIO DE FERRO E ACO LTDA | C25: SERVIÇOS ADVOCATÍCIOS | D25: 23300 | E25: 3662.5 | H25: 21/08/2025
A26: 15/06/2025 | B26: FAVIFER COMERCIO DE FERRO E ACO LTDA | C26: SERVIÇOS ADVOCATÍCIOS | E26: 3662.5 | H26: 22/08/2025
A27: 15/06/2025 | B27: FAVIFER COMERCIO DE FERRO E ACO LTDA | C27: SERVIÇOS ADVOCATÍCIOS | E27: 3662.5 | H27: 02/09/2025
A28: 15/06/2025 | B28: FAVIFER COMERCIO DE FERRO E ACO LTDA | C28: SERVIÇOS ADVOCATÍCIOS | E28: 3662.5 | F28: =D25-(SUM(E25:E28)) -> 8650 | G28: 11268.25 | H28: 09/09/2025
A29: 15/07/2025 | B29: FAVIFER COMERCIO DE FERRO E ACO LTDA | C29: SERVIÇOS ADVOCATÍCIOS | D29: 23300 | E29: 3662.5 | H29: 12/09/2025
A30: 15/07/2025 | B30: FAVIFER COMERCIO DE FERRO E ACO LTDA | C30: SERVIÇOS ADVOCATÍCIOS | E30: 3662.5 | H30: 29/09/2025
A31: 15/07/2025 | B31: FAVIFER COMERCIO DE FERRO E ACO LTDA | C31: SERVIÇOS ADVOCATÍCIOS | E31: 3662.5 | H31: 03/10/2025
A32: 15/07/2025 | B32: FAVIFER COMERCIO DE FERRO E ACO LTDA | C32: SERVIÇOS ADVOCATÍCIOS | E32: 3662.5 | F32: =D29-(SUM(E29:E32)) -> 8650 | G32: 11151.22 | H32: 10/10/2025
A33: 15/08/2025 | B33: FAVIFER COMERCIO DE FERRO E ACO LTDA | C33: SERVIÇOS ADVOCATÍCIOS | D33: 23300 | E33: 3662.5 | H33: 17/10/2025
A34: 15/08/2025 | B34: FAVIFER COMERCIO DE FERRO E ACO LTDA | C34: SERVIÇOS ADVOCATÍCIOS | E34: 3662.5 | H34: 24/10/2025
A35: 15/08/2025 | B35: FAVIFER COMERCIO DE FERRO E ACO LTDA | C35: SERVIÇOS ADVOCATÍCIOS | E35: 3662.5 | H35: 31/10/2025
A36: 15/08/2025 | B36: FAVIFER COMERCIO DE FERRO E ACO LTDA | C36: SERVIÇOS ADVOCATÍCIOS | E36: 2000 | H36: 07/11/2025
A37: 15/08/2025 | B37: FAVIFER COMERCIO DE FERRO E ACO LTDA | C37: SERVIÇOS ADVOCATÍCIOS | E37: 1662.5 | F37: =D33-(SUM(E33:E37)) -> 8650 | G37: 11027.03 | H37: 10/11/2025
A38: 15/09/2025 | B38: FAVIFER COMERCIO DE FERRO E ACO LTDA | C38: SERVIÇOS ADVOCATÍCIOS | D38: 23300 | E38: 3662.5 | H38: 14/11/2025
A39: 15/09/2025 | B39: FAVIFER COMERCIO DE FERRO E ACO LTDA | C39: SERVIÇOS ADVOCATÍCIOS | E39: 3662.5 | H39: 25/11/2025
A40: 15/09/2025 | B40: FAVIFER COMERCIO DE FERRO E ACO LTDA | C40: SERVIÇOS ADVOCATÍCIOS | E40: 3662.5 | H40: 28/11/2025
A41: 15/09/2025 | B41: FAVIFER COMERCIO DE FERRO E ACO LTDA | C41: SERVIÇOS ADVOCATÍCIOS | E41: 3662.5 | F41: =D38-(SUM(E38:E41)) -> 8650 | G41: 10954.85 | H41: 19/12/2025
...

Sheet FELICITA
A2: Data Vencimento | B2: Cliente | C2: Descrição | D2: Valor Faturado | E2: Valor Pago | F2: Valor em Aberto | G2: Valor Atualizado | H2: Data Baixa
A3: 15/01/2025 | B3: Felicita Importadora e Distribuidora de Alimentos | C3: SERVIÇOS ADVOCATÍCIOS | D3: 12500 | E3: 10000 | H3: 29/01/2025
A4: 15/01/2025 | B4: Felicita Importadora e Distribuidora de Alimentos | C4: SERVIÇOS ADVOCATÍCIOS | E4: 2500 | F4: 0 | G4: 0 | H4: 30/01/2025
A5: 15/02/2025 | B5: Felicita Importadora e Distribuidora de Alimentos | C5: SERVIÇOS ADVOCATÍCIOS | D5: 12500 | E5: 6500 | H5: 19/02/2025
A6: 15/02/2025 | B6: Felicita Importadora e Distribuidora de Alimentos | C6: SERVIÇOS ADVOCATÍCIOS | E6: 6000 | F6: 0 | G6: 0 | H6: 26/02/2025
A7: 15/03/2025 | B7: Felicita Importadora e Distribuidora de Alimentos | C7: SERVIÇOS ADVOCATÍCIOS | D7: 12500 | E7: 6500 | H7: 26/03/2025
A8: 15/03/2025 | B8: Felicita Importadora e Distribuidora de Alimentos | C8: SERVIÇOS ADVOCATÍCIOS | E8: 6000 | F8: 0 | G8: 0 | H8: 03/04/2025
A9: 15/04/2025 | B9: Felicita Importadora e Distribuidora de Alimentos | C9: SERVIÇOS ADVOCATÍCIOS | D9: 15000 | E9: 500 | H9: 03/04/2025
A10: 15/04/2025 | B10: Felicita Importadora e Distribuidora de Alimentos | C10: SERVIÇOS ADVOCATÍCIOS | E10: 14500 | F10: 0 | G10: 0 | H10: 26/05/2025
A11: 15/05/2025 | B11: Felicita Importadora e Distribuidora de Alimentos | C11: SERVIÇOS ADVOCATÍCIOS | D11: 15000 | E11: 500 | H11: 26/05/2025
A12: 15/05/2025 | B12: Felicita Importadora e Distribuidora de Alimentos | C12: SERVIÇOS ADVOCATÍCIOS | E12: 7500 | H12: 29/05/2025
A13: 15/05/2025 | B13: Felicita Importadora e Distribuidora de Alimentos | C13: SERVIÇOS ADVOCATÍCIOS | E13: 2000 | H13: 08/07/2025
A14: 15/05/2025 | B14: Felicita Importadora e Distribuidora de Alimentos | C14: SERVIÇOS ADVOCATÍCIOS | E14: 4000 | H14: 24/09/2025
A15: 15/05/2025 | B15: Felicita Importadora e Distribuidora de Alimentos | C15: SERVIÇOS ADVOCATÍCIOS | E15: 1000 | F15: 0 | G15: 0 | H15: 02/10/2025
A16: 15/06/2025 | B16: Felicita Importadora e Distribuidora de Alimentos | C16: SERVIÇOS ADVOCATÍCIOS | D16: 15000 | E16: 3000 | H16: 02/10/2025
A17: 15/06/2025 | B17: Felicita Importadora e Distribuidora de Alimentos | C17: SERVIÇOS ADVOCATÍCIOS | E17: 4000 | H17: 10/10/2025
A18: 15/06/2025 | B18: Felicita Importadora e Distribuidora de Alimentos | C18: SERVIÇOS ADVOCATÍCIOS | E18: 5000 | H18: 14/11/2025
A19: 15/06/2025 | B19: Felicita Importadora e Distribuidora de Alimentos | C19: SERVIÇOS ADVOCATÍCIOS | E19: 3000 | F19: 0 | G19: 0 | H19: 24/11/2025
A20: 15/07/2025 | B20: Felicita Importadora e Distribuidora de Alimentos | C20: SERVIÇOS ADVOCATÍCIOS | D20: 15000 | E20: 1000 | H20: 24/11/2025
A21: 15/07/2025 | B21: Felicita Importadora e Distribuidora de Alimentos | C21: SERVIÇOS ADVOCATÍCIOS | E21: 14000 | F21: 0 | G21: 0 | H21: 18/12/2025
A22: 15/08/2025 | B22: Felicita Importadora e Distribuidora de Alimentos | C22: SERVIÇOS ADVOCATÍCIOS | D22: 15000 | E22: 1000 | H22: 18/12/2025
A23: 15/08/2025 | B23: Felicita Importadora e Distribuidora de Alimentos | C23: SERVIÇOS ADVOCATÍCIOS | E23: 6000 | H23: 26/01/2026
A24: 15/08/2025 | B24: Felicita Importadora e Distribuidora de Alimentos | C24: SERVIÇOS ADVOCATÍCIOS | E24: 0 | F24: =D22-E22-E23 -> 8000 | G24: 10198.42 | H24: 00/00/0000
A25: 15/09/2025 | B25: Felicita Importadora e Distribuidora de Alimentos | C25: SERVIÇOS ADVOCATÍCIOS | D25: 15000 | E25: 0 | F25: =D25-E25 -> 15000 | G25: 18996.86 | H25: 00/00/0000
A26: 15/10/2025 | B26: Felicita Importadora e Distribuidora de Alimentos | C26: SERVIÇOS ADVOCATÍCIOS | D26: 15000 | E26: 0 | F26: =D26-E26 -> 15000 | G26: 18754.87 | H26: 00/00/0000
A27: 04/11/2025 | B27: Felicita Importadora e Distribuidora de Alimentos | C27: REEMBOLSO | D27: 938.6 | E27: 938.6 | F27: =D27-E27 -> 0 | G27: 0 | H27: 04/11/2025
A28: 15/11/2025 | B28: Felicita Importadora e Distribuidora de Alimentos | C28: SERVIÇOS ADVOCATÍCIOS | D28: 15000 | E28: 0 | F28: =D28-E28 -> 15000 | G28: 18570.18 | H28: 00/00/0000
A29: 15/12/2025 | B29: Felicita Importadora e Distribuidora de Alimentos | C29: SERVIÇOS ADVOCATÍCIOS | D29: 15000 | E29: 0 | F29: =D29-E29 -> 15000 | G29: 18382.45 | H29: 00/00/0000
A30: 15/01/2026 | B30: Felicita Importadora e Distribuidora de Alimentos | C30: SERVIÇOS ADVOCATÍCIOS | D30: 15000 | E30: 0 | F30: =D30-E30 -> 15000 | G30: 18186.3 | H30: 00/00/0000
F31: =SUM(F3:F30) -> 83000 | G31: =SUM(G3:G30) -> 103089.08

Sheet FERRAMENTARIA GASPEC
A2: Data Vencimento | B2: Cliente | C2: Descrição | D2: Valor Faturado | E2: Valor Pago | F2: Valor em Aberto | G2: Valor Atualizado | H2: Data Baixa
A3: 28/07/2025 | B3: Ferramentaria Gaspec Ltda Em Recuperacao Judicial | C3: ACORDO HONORÁRIOS REF. 2023 E 2024 | D3: 9086.1 | E3: 0 | F3: 9086.1 | G3: 9868.79 | H3: 00/00/0000
A4: 28/08/2025 | B4: Ferramentaria Gaspec Ltda Em Recuperacao Judicial | C4: ACORDO HONORÁRIOS REF. 2023 E 2024 | D4: 9086.1 | E4: 0 | F4: 9086.1 | G4: 9744.41 | H4: 00/00/0000
A5: 28/09/2025 | B5: Ferramentaria Gaspec Ltda Em Recuperacao Judicial | C5: ACORDO HONORÁRIOS REF. 2023 E 2024 | D5: 9086.1 | E5: 0 | F5: 9086.1 | G5: 9666.01 | H5: 00/00/0000
A6: 28/10/2025 | B6: Ferramentaria Gaspec Ltda Em Recuperacao Judicial | C6: ACORDO HONORÁRIOS REF. 2023 E 2024 | D6: 9086.1 | E6: 0 | F6: 9086.1 | G6: 9528.22 | H6: 00/00/0000
A7: 28/11/2025 | B7: Ferramentaria Gaspec Ltda Em Recuperacao Judicial | C7: ACORDO HONORÁRIOS REF. 2023 E 2024 | D7: 9086.1 | E7: 0 | F7: 9086.1 | G7: 9419.65 | H7: 00/00/0000
A8: 28/12/2025 | B8: Ferramentaria Gaspec Ltda Em Recuperacao Judicial | C8: ACORDO HONORÁRIOS REF. 2023 E 2024 | D8: 9086.1 | E8: 0 | F8: 9086.1 | G8: 9309.57 | H8: 00/00/0000
A9: 10/01/2026 | B9: Ferramentaria Gaspec Ltda Em Recuperacao Judicial | C9: SERVIÇOS ADVOCATÍCIOS | D9: 15913.9 | E9: 0 | F9: 15913.9 | G9: 16105.19 | H9: 00/00/0000
A10: 10/01/2026 | B10: Ferramentaria Gaspec Ltda Em Recuperacao Judicial | C10: SERVIÇOS ADVOCATÍCIOS | D10: 3592.81 | E10: 0 | F10: 3592.81 | G10: 3636 | H10: 00/00/0000
A11: 28/01/2026 | B11: Ferramentaria Gaspec Ltda Em Recuperacao Judicial | C11: ACORDO HONORÁRIOS REF. 2023 E 2024 | D11: 9086.1 | E11: 0 | F11: 9086.1 | G11: 9195.31 | H11: 00/00/0000
A12: 46063 | B12: Ferramentaria Gaspec Ltda Em Recuperacao Judicial | C12: SERVIÇOS ADVOCATÍCIOS | D12: 15913.9 | E12: 0 | F12: =D12-E12 -> 15913.9
A13: 46063 | B13: Ferramentaria Gaspec Ltda Em Recuperacao Judicial | C13: SERVIÇOS ADVOCATÍCIOS | D13: 3592.81 | E13: 0 | F13: =D13-E13 -> 3592.81
F14: =SUM(F3:F13) -> 102616.12 | G14: =SUM(G3:G11) -> 86473.15

Sheet FORM BOB
A2: Data Vencimento | B2: Cliente | C2: Descrição | D2: Valor Faturado | E2: Valor Pago | F2: Valor em Aberto | G2: Valor Atualizado | H2: Data Baixa
A3: 18/04/2025 | B3: Form Bob Papeis Ltda | C3: SERVIÇOS ADVOCATÍCIOS | D3: 10000 | E3: 3000 | F3: =D3-E3 -> 7000 | G3: 9334.61 | H3: 00/00/0000
A4: 45795 | B4: Form Bob Papeis Ltda | C4: SERVIÇOS ADVOCATÍCIOS | D4: 10000 | E4: 0 | F4: 10000 | G4: 13175.92 | H4: 00/00/0000
A5: 18/06/2025 | B5: Form Bob Papeis Ltda | C5: SERVIÇOS ADVOCATÍCIOS | D5: 10000 | E5: 0 | F5: 10000 | G5: 13026.88 | H5: 00/00/0000
A6: 18/07/2025 | B6: Form Bob Papeis Ltda | C6: SERVIÇOS ADVOCATÍCIOS | D6: 10000 | E6: 0 | F6: 10000 | G6: 12891.59 | H6: 00/00/0000
A7: 18/08/2025 | B7: Form Bob Papeis Ltda | C7: SERVIÇOS ADVOCATÍCIOS | D7: 10000 | E7: 0 | F7: 10000 | G7: 12748.01 | H7: 00/00/0000
A8: 18/09/2025 | B8: Form Bob Papeis Ltda | C8: SERVIÇOS ADVOCATÍCIOS | D8: 10000 | E8: 0 | F8: 10000 | G8: 12664.57 | H8: 00/00/0000
A9: 18/10/2025 | B9: Form Bob Papeis Ltda | C9: SERVIÇOS ADVOCATÍCIOS | D9: 10000 | E9: 0 | F9: 10000 | G9: 12503.24 | H9: 00/00/0000
A10: 18/11/2025 | B10: Form Bob Papeis Ltda | C10: SERVIÇOS ADVOCATÍCIOS | D10: 10000 | E10: 0 | F10: 10000 | G10: 12380.12 | H10: 00/00/0000
A11: 18/12/2025 | B11: Form Bob Papeis Ltda | C11: SERVIÇOS ADVOCATÍCIOS | D11: 10000 | E11: 0 | F11: 10000 | G11: 12254.96 | H11: 00/00/0000
A12: 18/01/2026 | B12: Form Bob Papeis Ltda | C12: SERVIÇOS ADVOCATÍCIOS | D12: 10000 | E12: 0 | F12: 10000 | G12: 12124.2 | H12: 00/00/0000
F13: =SUM(F3:F12) -> 97000 | G13: =SUM(G3:G12) -> 123104.1

Sheet GRUPO IBS
A2: Data Vencimento | B2: Cliente | C2: Descrição | D2: Valor Faturado | E2: Valor Pago | F2: Valor em Aberto | G2: Data Baixa
A3: 20/01/2025 | B3: IBS INDUSTRIA BRASILEIRA DE SUCOS S/A | C3: SERVIÇOS ADVOCATÍCIOS | D3: 10000 | E3: 0 | F3: 10000 | G3: 00/00/0000
A4: 20/02/2025 | B4: IBS INDUSTRIA BRASILEIRA DE SUCOS S/A | C4: SERVIÇOS ADVOCATÍCIOS | D4: 10000 | E4: 0 | F4: 10000 | G4: 00/00/0000
A5: 20/03/2025 | B5: IBS INDUSTRIA BRASILEIRA DE SUCOS S/A | C5: SERVIÇOS ADVOCATÍCIOS | D5: 10000 | E5: 0 | F5: 10000 | G5: 00/00/0000
A6: 20/04/2025 | B6: IBS INDUSTRIA BRASILEIRA DE SUCOS S/A | C6: SERVIÇOS ADVOCATÍCIOS | D6: 10000 | E6: 0 | F6: 10000 | G6: 00/00/0000
A7: 20/05/2025 | B7: IBS INDUSTRIA BRASILEIRA DE SUCOS S/A | C7: SERVIÇOS ADVOCATÍCIOS | D7: 10000 | E7: 0 | F7: 10000 | G7: 00/00/0000
A8: 20/06/2025 | B8: IBS INDUSTRIA BRASILEIRA DE SUCOS S/A | C8: SERVIÇOS ADVOCATÍCIOS | D8: 10000 | E8: 0 | F8: 10000 | G8: 00/00/0000
A9: 20/07/2025 | B9: IBS INDUSTRIA BRASILEIRA DE SUCOS S/A | C9: SERVIÇOS ADVOCATÍCIOS | D9: 10000 | E9: 0 | F9: 10000 | G9: 00/00/0000
A10: 20/08/2025 | B10: IBS INDUSTRIA BRASILEIRA DE SUCOS S/A | C10: SERVIÇOS ADVOCATÍCIOS | D10: 10000 | E10: 0 | F10: 10000 | G10: 00/00/0000
A11: 20/09/2025 | B11: IBS INDUSTRIA BRASILEIRA DE SUCOS S/A | C11: SERVIÇOS ADVOCATÍCIOS | D11: 10000 | E11: 0 | F11: 10000 | G11: 00/00/0000
A12: 20/10/2025 | B12: IBS INDUSTRIA BRASILEIRA DE SUCOS S/A | C12: SERVIÇOS ADVOCATÍCIOS | D12: 10000 | E12: 0 | F12: 10000 | G12: 00/00/0000
A13: 20/11/2025 | B13: IBS INDUSTRIA BRASILEIRA DE SUCOS S/A | C13: SERVIÇOS ADVOCATÍCIOS | D13: 10000 | E13: 0 | F13: 10000 | G13: 00/00/0000
A14: 20/12/2025 | B14: IBS INDUSTRIA BRASILEIRA DE SUCOS S/A | C14: SERVIÇOS ADVOCATÍCIOS | D14: 10000 | E14: 0 | F14: 10000 | G14: 00/00/0000
A15: 20/01/2026 | B15: IBS INDUSTRIA BRASILEIRA DE SUCOS S/A | C15: SERVIÇOS ADVOCATÍCIOS | D15: 10000 | E15: 0 | F15: 10000 | G15: 00/00/0000
F16: =SUM(F3:F15) -> 130000

Sheet LINOPLAST
A2: Data Vencimento | B2: Cliente | C2: Descrição | D2: Valor Faturado | E2: Valor Pago | F2: Valor em Aberto | G2: Valor Atualizado | H2: Data Baixa
A3: 26/12/2025 | B3: Linoplast Industria e Comercio Ltda | C3: SERVIÇOS ADVOCATÍCIOS | D3: 15000 | E3: 0 | F3: 15000 | G3: 18382.45 | H3: 00/00/0000
A4: 26/01/2026 | B4: Linoplast Industria e Comercio Ltda | C4: SERVIÇOS ADVOCATÍCIOS | D4: 15000 | E4: 0 | F4: 15000 | G4: 18186.3 | H4: 00/00/0000
F5: =SUM(F3:F4) -> 30000 | G5: =SUM(G3:G4) -> 36568.75

Sheet LIRA
A2: Data Vencimento | B2: Cliente | C2: Descrição | D2: Valor Faturado | E2: Valor Pago | F2: Valor em Aberto | G2: Data Baixa
A3: 05/07/2025 | B3: LIRA ALIMENTOS INDUSTRIA E COMERCIO LTDA | C3: SERVIÇOS ADVOCATÍCIOS | D3: 15000 | E3: 10000 | F3: 5000 | G3: 00/00/0000
A4: 05/08/2025 | B4: LIRA ALIMENTOS INDUSTRIA E COMERCIO LTDA | C4: SERVIÇOS ADVOCATÍCIOS | D4: 15000 | E4: 0 | F4: 15000 | G4: 00/00/0000
A5: 05/09/2025 | B5: LIRA ALIMENTOS INDUSTRIA E COMERCIO LTDA | C5: SERVIÇOS ADVOCATÍCIOS | D5: 15000 | E5: 0 | F5: 15000 | G5: 00/00/0000
A6: 05/10/2025 | B6: LIRA ALIMENTOS INDUSTRIA E COMERCIO LTDA | C6: SERVIÇOS ADVOCATÍCIOS | D6: 15000 | E6: 0 | F6: 15000 | G6: 00/00/0000
A7: 05/11/2025 | B7: LIRA ALIMENTOS INDUSTRIA E COMERCIO LTDA | C7: SERVIÇOS ADVOCATÍCIOS | D7: 15000 | E7: 0 | F7: 15000 | G7: 00/00/0000
A8: 05/12/2025 | B8: LIRA ALIMENTOS INDUSTRIA E COMERCIO LTDA | C8: SERVIÇOS ADVOCATÍCIOS | D8: 15000 | E8: 0 | F8: 15000 | G8: 00/00/0000
A9: 05/01/2026 | B9: LIRA ALIMENTOS INDUSTRIA E COMERCIO LTDA | C9: SERVIÇOS ADVOCATÍCIOS | D9: 15000 | E9: 0 | F9: 15000 | G9: 00/00/0000
A10: 46058 | B10: LIRA ALIMENTOS INDUSTRIA E COMERCIO LTDA | C10: SERVIÇOS ADVOCATÍCIOS | D10: 15000 | E10: 0 | F10: =D10-E10 -> 15000
F11: =SUM(F3:F10) -> 110000

Sheet LIVRARIA CULTURA
A1: Saldo devedor aditivo: R$ 238.522,70, sendo R$ 2.000,00 de amortização por mês de outubro/2024 a fevereiro/2025 e R$ 12.000,00 de março/2025 em diante (20 parcelas?).
A2: Data Vencimento | B2: Cliente | C2: Descrição | D2: Valor Faturado | E2: Valor Pago | F2: Valor em Aberto | G2: Valor Atualizado | H2: Data Baixa
A3: 15/10/2024 | B3: Livraria Cultura Ltda. - Em Recuperacao Judicial Em Recuperacao Judicial | C3: SERVIÇOS ADVOCATÍCIOS | D3: 20000 | E3: 5000 | H3: 10/10/2024
A4: 15/10/2024 | B4: Livraria Cultura Ltda. - Em Recuperacao Judicial Em Recuperacao Judicial | C4: SERVIÇOS ADVOCATÍCIOS | E4: 5000 | H4: 22/10/2024
A5: 15/10/2024 | B5: Livraria Cultura Ltda. - Em Recuperacao Judicial Em Recuperacao Judicial | C5: SERVIÇOS ADVOCATÍCIOS | E5: 6000 | H5: 25/10/2024
A6: 15/10/2024 | B6: Livraria Cultura Ltda. - Em Recuperacao Judicial Em Recuperacao Judicial | C6: SERVIÇOS ADVOCATÍCIOS | E6: 1000 | H6: 28/10/2024
A7: 15/10/2024 | B7: Livraria Cultura Ltda. - Em Recuperacao Judicial Em Recuperacao Judicial | C7: SERVIÇOS ADVOCATÍCIOS | E7: 1000 | H7: 01/11/2024
A8: 15/10/2024 | B8: Livraria Cultura Ltda. - Em Recuperacao Judicial Em Recuperacao Judicial | C8: SERVIÇOS ADVOCATÍCIOS | E8: 1000 | H8: 04/11/2024
A9: 15/10/2024 | B9: Livraria Cultura Ltda. - Em Recuperacao Judicial Em Recuperacao Judicial | C9: SERVIÇOS ADVOCATÍCIOS | E9: 1000 | F9: =D3-SUM(E3:E9) -> 0 | G9: 0 | H9: 12/11/2024
A10: 15/11/2024 | B10: Livraria Cultura Ltda. - Em Recuperacao Judicial Em Recuperacao Judicial | C10: SERVIÇOS ADVOCATÍCIOS | D10: 20000 | E10: 1000 | H10: 19/11/2024
A11: 15/11/2024 | B11: Livraria Cultura Ltda. - Em Recuperacao Judicial Em Recuperacao Judicial | C11: SERVIÇOS ADVOCATÍCIOS | E11: 500 | H11: 22/11/2024
A12: 15/11/2024 | B12: Livraria Cultura Ltda. - Em Recuperacao Judicial Em Recuperacao Judicial | C12: SERVIÇOS ADVOCATÍCIOS | E12: 700 | H12: 29/11/2024
A13: 15/11/2024 | B13: Livraria Cultura Ltda. - Em Recuperacao Judicial Em Recuperacao Judicial | C13: SERVIÇOS ADVOCATÍCIOS | E13: 1000 | H13: 10/12/2024
A14: 15/11/2024 | B14: Livraria Cultura Ltda. - Em Recuperacao Judicial Em Recuperacao Judicial | C14: SERVIÇOS ADVOCATÍCIOS | E14: 1000 | H14: 17/12/2024
A15: 15/11/2024 | B15: Livraria Cultura Ltda. - Em Recuperacao Judicial Em Recuperacao Judicial | C15: SERVIÇOS ADVOCATÍCIOS | E15: 1000 | H15: 24/12/2024
A16: 15/11/2024 | B16: Livraria Cultura Ltda. - Em Recuperacao Judicial Em Recuperacao Judicial | C16: SERVIÇOS ADVOCATÍCIOS | E16: 500 | H16: 06/01/2025
A17: 15/11/2024 | B17: Livraria Cultura Ltda. - Em Recuperacao Judicial Em Recuperacao Judicial | C17: SERVIÇOS ADVOCATÍCIOS | E17: 1000 | H17: 13/01/2025
A18: 15/11/2024 | B18: Livraria Cultura Ltda. - Em Recuperacao Judicial Em Recuperacao Judicial | C18: SERVIÇOS ADVOCATÍCIOS | E18: 1000 | H18: 14/01/2025
A19: 15/11/2024 | B19: Livraria Cultura Ltda. - Em Recuperacao Judicial Em Recuperacao Judicial | C19: SERVIÇOS ADVOCATÍCIOS | E19: 1000 | H19: 17/01/2025
A20: 15/11/2024 | B20: Livraria Cultura Ltda. - Em Recuperacao Judicial Em Recuperacao Judicial | C20: SERVIÇOS ADVOCATÍCIOS | E20: 500 | H20: 21/01/2025
A21: 15/11/2024 | B21: Livraria Cultura Ltda. - Em Recuperacao Judicial Em Recuperacao Judicial | C21: SERVIÇOS ADVOCATÍCIOS | E21: 1000 | H21: 07/01/2025
A22: 15/11/2024 | B22: Livraria Cultura Ltda. - Em Recuperacao Judicial Em Recuperacao Judicial | C22: SERVIÇOS ADVOCATÍCIOS | E22: 500 | H22: 16/01/2025
... A29: 15/11/2024 | B29: Livraria Cultura Ltda. - Em Recuperacao Judicial Em Recuperacao Judicial | C29: SERVIÇOS ADVOCATÍCIOS | E29: 1000 | H29: 25/03/2025
A30: 15/11/2024 | B30: Livraria Cultura Ltda. - Em Recuperacao Judicial Em Recuperacao Judicial | C30: SERVIÇOS ADVOCATÍCIOS | E30: 3800 | F30: =D10-SUM(E10:E30) -> 0 | G30: 0 | H30: 31/03/2025
A31: 15/12/2024 | B31: Livraria Cultura Ltda. - Em Recuperacao Judicial Em Recuperacao Judicial | C31: SERVIÇOS ADVOCATÍCIOS | D31: 20000 | E31: 10700 | H31: 31/03/2025
A32: 15/12/2024 | B32: Livraria Cultura Ltda. - Em Recuperacao Judicial Em Recuperacao Judicial | C32: SERVIÇOS ADVOCATÍCIOS | E32: 1000 | H32: 08/04/2025
A33: 15/12/2024 | B33: Livraria Cultura Ltda. - Em Recuperacao Judicial Em Recuperacao Judicial | C33: SERVIÇOS ADVOCATÍCIOS | E33: 8300 | F33: =D31-SUM(E31:E33) -> 0 | G33: 0 | H33: 30/04/2025
A34: 15/01/2025 | B34: Livraria Cultura Ltda. - Em Recuperacao Judicial Em Recuperacao Judicial | C34: SERVIÇOS ADVOCATÍCIOS | D34: 20000 | E34: 20000 | F34: =D34-E34 -> 0 | G34: 0 | H34: 30/04/2025
A35: 15/02/2025 | B35: Livraria Cultura Ltda. - Em Recuperacao Judicial Em Recuperacao Judicial | C35: SERVIÇOS ADVOCATÍCIOS | D35: 20000 | E35: 1700 | H35: 30/04/2025
A36: 15/02/2025 | B36: Livraria Cultura Ltda. - Em Recuperacao Judicial Em Recuperacao Judicial | C36: SERVIÇOS ADVOCATÍCIOS | E36: 12000 | H36: 26/05/2025
A37: 15/02/2025 | B37: Livraria Cultura Ltda. - Em Recuperacao Judicial Em Recuperacao Judicial | C37: SERVIÇOS ADVOCATÍCIOS | E37: 6300 | F37: =D35-SUM(E35:E37) -> 0 | G37: 0 | H37: 27/05/2025
A38: 15/03/2025 | B38: Livraria Cultura Ltda. - Em Recuperacao Judicial Em Recuperacao Judicial | C38: SERVIÇOS ADVOCATÍCIOS | D38: 30000 | E38: 3700 | H38: 27/05/2025
A39: 15/03/2025 | B39: Livraria Cultura Ltda. - Em Recuperacao Judicial Em Recuperacao Judicial | C39: SERVIÇOS ADVOCATÍCIOS | E39: 10000 | H39: 28/05/2025
A40: 15/03/2025 | B40: Livraria Cultura Ltda. - Em Recuperacao Judicial Em Recuperacao Judicial | C40: SERVIÇOS ADVOCATÍCIOS | E40: 5000 | H40: 29/05/2025
A41: 15/03/2025 | B41: Livraria Cultura Ltda. - Em Recuperacao Judicial Em Recuperacao Judicial | C41: SERVIÇOS ADVOCATÍCIOS | E41: 1300 | H41: 30/05/2025
A42: 15/03/2025 | B42: Livraria Cultura Ltda. - Em Recuperacao Judicial Em Recuperacao Judicial | C42: SERVIÇOS ADVOCATÍCIOS | E42: 0 | F42: =D38-SUM(E38:E42) -> 10000 | G42: 11665.51 | H42: 00/00/0000
A43: 15/04/2025 | B43: Livraria Cultura Ltda. - Em Recuperacao Judicial Em Recuperacao Judicial | C43: SERVIÇOS ADVOCATÍCIOS | D43: 30000 | E43: 8700 | H43: 30/05/2025
A44: 15/04/2025 | B44: Livraria Cultura Ltda. - Em Recuperacao Judicial Em Recuperacao Judicial | C44: SERVIÇOS ADVOCATÍCIOS | E44: 11300 | H44: 02/06/2025
A45: 15/04/2025 | B45: Livraria Cultura Ltda. - Em Recuperacao Judicial Em Recuperacao Judicial | C45: SERVIÇOS ADVOCATÍCIOS | E45: 0 | F45: =D43-SUM(E43:E45) -> 10000 | G45: 11488.75 | H45: 00/00/0000
A46: 15/05/2025 | B46: Livraria Cultura Ltda. - Em Recuperacao Judicial Em Recuperacao Judicial | C46: SERVIÇOS ADVOCATÍCIOS | D46: 30000 | E46: 9700 | H46: 02/06/2025
...

Sheet LOYAL
A2: Data Vencimento | B2: Cliente | C2: Descrição | D2: Valor Faturado | E2: Valor Pago | F2: Valor em Aberto | G2: Valor Atualizado | H2: Data Baixa
A3: 29/05/2025 | B3: LOYAL PROFIT CONSULTING LTDA | C3: SERVIÇOS ADVOCATÍCIOS | D3: 3237.02 | E3: 2814.9 | F3: 422.12 | G3: 556.18 | H3: 00/00/0000
A4: 29/06/2025 | B4: LOYAL PROFIT CONSULTING LTDA | C4: SERVIÇOS ADVOCATÍCIOS | D4: 3237.02 | E4: 0 | F4: 3237.02 | G4: 4216.83 | H4: 00/00/0000
A5: 29/07/2025 | B5: LOYAL PROFIT CONSULTING LTDA | C5: SERVIÇOS ADVOCATÍCIOS | D5: 3237.02 | E5: 0 | F5: 3237.02 | G5: 4173.03 | H5: 00/00/0000
A6: 29/08/2025 | B6: LOYAL PROFIT CONSULTING LTDA | C6: SERVIÇOS ADVOCATÍCIOS | D6: 3237.02 | E6: 0 | F6: 3237.02 | G6: 4126.56 | H6: 00/00/0000
A7: 29/09/2025 | B7: LOYAL PROFIT CONSULTING LTDA | C7: SERVIÇOS ADVOCATÍCIOS | D7: 3237.02 | E7: 0 | F7: 3237.02 | G7: 4099.55 | H7: 00/00/0000
A8: 29/10/2025 | B8: LOYAL PROFIT CONSULTING LTDA | C8: SERVIÇOS ADVOCATÍCIOS | D8: 3237.02 | E8: 0 | F8: 3237.02 | G8: 4047.32 | H8: 00/00/0000
A9: 29/11/2025 | B9: LOYAL PROFIT CONSULTING LTDA | C9: SERVIÇOS ADVOCATÍCIOS | D9: 3237.02 | E9: 0 | F9: 3237.02 | G9: 4007.47 | H9: 00/00/0000
A10: 29/12/2025 | B10: LOYAL PROFIT CONSULTING LTDA | C10: SERVIÇOS ADVOCATÍCIOS | D10: 3237.02 | E10: 0 | F10: 3237.02 | G10: 3966.95 | H10: 00/00/0000
A11: 46051 | B11: LOYAL PROFIT CONSULTING LTDA | C11: SERVIÇOS ADVOCATÍCIOS | D11: 3237.02 | E11: 0 | F11: 3237.02 | G11: 3924.62 | H11: 00/00/0000
F12: =SUM(F3:F11) -> 26318.28 | G12: =SUM(G3:G11) -> 33118.51

Sheet MAZDA
A2: Data Vencimento | B2: Cliente | C2: Descrição | D2: Valor Faturado | E2: Valor Pago | F2: Valor em Aberto | G2: Data Baixa
A3: 30/08/2025 | B3: MAZDA EMBALAGENS LTDA EM RECUPERACAO JUDICIAL | C3: SERVIÇOS ADVOCATÍCIOS | D3: 16800 | E3: 14619.18 | F3: 2180.82 | G3: 00/00/0000
A4: 30/09/2025 | B4: MAZDA EMBALAGENS LTDA EM RECUPERACAO JUDICIAL | C4: SERVIÇOS ADVOCATÍCIOS | D4: 16800 | E4: 0 | F4: 16800 | G4: 00/00/0000
A5: 30/10/2025 | B5: MAZDA EMBALAGENS LTDA EM RECUPERACAO JUDICIAL | C5: SERVIÇOS ADVOCATÍCIOS | D5: 15720 | E5: 0 | F5: 15720 | G5: 00/00/0000
A6: 30/11/2025 | B6: MAZDA EMBALAGENS LTDA EM RECUPERACAO JUDICIAL | C6: SERVIÇOS ADVOCATÍCIOS | D6: 15720 | E6: 0 | F6: 15720 | G6: 00/00/0000
A7: 30/12/2025 | B7: MAZDA EMBALAGENS LTDA EM RECUPERACAO JUDICIAL | C7: SERVIÇOS ADVOCATÍCIOS | D7: 15648 | E7: 0 | F7: 15648 | G7: 00/00/0000
A8: 46052 | B8: MAZDA EMBALAGENS LTDA EM RECUPERACAO JUDICIAL | C8: SERVIÇOS ADVOCATÍCIOS | D8: 15288 | E8: 0 | F8: 15288 | G8: 00/00/0000
F9: =SUM(F3:F8) -> 81356.82
A12: Novo acordo em janeiro/2026 - 11 parcelas de R$ 6.606,88 com pagamento quinzenal + honorário do mês

Sheet METALCASTY
A2: Data Vencimento | B2: Cliente | C2: Descrição | D2: Valor Faturado | E2: Valor Pago | F2: Valor em Aberto | G2: Data Baixa
A3: 20/12/2024 | B3: METALCASTY LTDA EM RECUPERACAO JUDICIAL | C3: DIFERENÇA REF. 2023 E 2024, APÓS CONFERÊNCIA FELIPE E JULIANA | D3: 18819.25 | E3: 0 | F3: 18819.25 | G3: 00/00/0000
A4: 20/09/2025 | B4: METALCASTY LTDA EM RECUPERACAO JUDICIAL | C4: SERVIÇOS ADVOCATÍCIOS | D4: 1080 | E4: 0 | F4: 1080 | G4: 00/00/0000
A5: 20/09/2025 | B5: METALCASTY LTDA EM RECUPERACAO JUDICIAL | C5: SERVIÇOS ADVOCATÍCIOS | D5: 8961.25 | E5: 0 | F5: 8961.25 | G5: 00/00/0000
A6: 20/10/2025 | B6: METALCASTY LTDA EM RECUPERACAO JUDICIAL | C6: SERVIÇOS ADVOCATÍCIOS | D6: 51845 | E6: 0 | F6: 51845 | G6: 00/00/0000
A7: 20/10/2025 | B7: METALCASTY LTDA EM RECUPERACAO JUDICIAL | C7: SERVIÇOS ADVOCATÍCIOS | D7: 1080 | E7: 0 | F7: 1080 | G7: 00/00/0000
A8: 20/11/2025 | B8: METALCASTY LTDA EM RECUPERACAO JUDICIAL | C8: SERVIÇOS ADVOCATÍCIOS | D8: 51845 | E8: 0 | F8: 51845 | G8: 00/00/0000
A9: 20/11/2025 | B9: METALCASTY LTDA EM RECUPERACAO JUDICIAL | C9: SERVIÇOS ADVOCATÍCIOS | D9: 1080 | E9: 0 | F9: 1080 | G9: 00/00/0000
A10: 20/12/2025 | B10: METALCASTY LTDA EM RECUPERACAO JUDICIAL | C10: SERVIÇOS ADVOCATÍCIOS | D10: 51845 | E10: 0 | F10: 51845 | G10: 00/00/0000
A11: 20/12/2025 | B11: METALCASTY LTDA EM RECUPERACAO JUDICIAL | C11: SERVIÇOS ADVOCATÍCIOS | D11: 1080 | E11: 0 | F11: 1080 | G11: 00/00/0000
A12: 20/01/2026 | B12: METALCASTY LTDA EM RECUPERACAO JUDICIAL | C12: SERVIÇOS ADVOCATÍCIOS | D12: 1080 | E12: 0 | F12: 1080 | G12: 00/00/0000
A13: 20/01/2026 | B13: METALCASTY LTDA EM RECUPERACAO JUDICIAL | C13: SERVIÇOS ADVOCATÍCIOS | D13: 51845 | E13: 0 | F13: 51845 | G13: 00/00/0000
F14: =SUM(F3:F13) -> 240560.5

Sheet MOVENT
A2: Data Vencimento | B2: Cliente | C2: Descrição | D2: Valor Faturado | E2: Valor Pago | F2: Valor em Aberto | G2: Data Baixa
A3: 30/08/2025 | B3: Movent Automotive Industria e Comercio de Autopecas Ltda | C3: SERVIÇOS ADVOCATÍCIOS | D3: 38000 | E3: 0 | F3: 38000 | G3: 00/00/0000
A4: 30/09/2025 | B4: Movent Automotive Industria e Comercio de Autopecas Ltda | C4: SERVIÇOS ADVOCATÍCIOS | D4: 38000 | E4: 0 | F4: 38000 | G4: 00/00/0000
A5: 30/10/2025 | B5: Movent Automotive Industria e Comercio de Autopecas Ltda | C5: SERVIÇOS ADVOCATÍCIOS | D5: 38000 | E5: 0 | F5: 38000 | G5: 00/00/0000
A6: 30/11/2025 | B6: Movent Automotive Industria e Comercio de Autopecas Ltda | C6: SERVIÇOS ADVOCATÍCIOS | D6: 38000 | E6: 0 | F6: 38000 | G6: 00/00/0000
A7: 30/12/2025 | B7: Movent Automotive Industria e Comercio de Autopecas Ltda | C7: SERVIÇOS ADVOCATÍCIOS | D7: 38000 | E7: 0 | F7: 38000 | G7: 00/00/0000
F8: =SUM(F3:F7) -> 190000

Sheet OFFICER-LUCIANO
A2: Data Vencimento | B2: Cliente | C2: Descrição | D2: Valor Faturado | E2: Valor Pago | F2: Valor em Aberto | G2: Valor Atualizado | H2: Data Baixa
A3: 15/01/2025 | B3: OFFICER S. A. DISTRIBUIDORA DE PRODUTOS DE TECNOLOGIA | C3: SERVIÇOS ADVOCATÍCIOS | D3: 17000 | E3: 5078.75 | F3: 11921.25 | G3: 16587.67 | H3: 00/00/0000
A4: 12/02/2025 | B4: OFFICER S. A. DISTRIBUIDORA DE PRODUTOS DE TECNOLOGIA | C4: SERVIÇOS ADVOCATÍCIOS - CONTRATO SOFISA | D4: 24000 | E4: 0 | F4: 24000 | G4: 33106.99 | H4: 00/00/0000
A5: 15/02/2025 | B5: OFFICER S. A. DISTRIBUIDORA DE PRODUTOS DE TECNOLOGIA | C5: SERVIÇOS ADVOCATÍCIOS | D5: 17000 | E5: 0 | F5: 17000 | G5: 23450.79 | H5: 00/00/0000
A6: 12/03/2025 | B6: OFFICER S. A. DISTRIBUIDORA DE PRODUTOS DE TECNOLOGIA | C6: SERVIÇOS ADVOCATÍCIOS - CONTRATO SOFISA | D6: 24000 | E6: 0 | F6: 24000 | G6: 32456.95 | H6: 00/00/0000
A7: 15/03/2025 | B7: OFFICER S. A. DISTRIBUIDORA DE PRODUTOS DE TECNOLOGIA | C7: SERVIÇOS ADVOCATÍCIOS | D7: 17000 | E7: 0 | F7: 17000 | G7: 22990.35 | H7: 00/00/0000
A8: 12/04/2025 | B8: OFFICER S. A. DISTRIBUIDORA DE PRODUTOS DE TECNOLOGIA | C8: SERVIÇOS ADVOCATÍCIOS - CONTRATO SOFISA | D8: 24000 | E8: 0 | F8: 24000 | G8: 32004.36 | H8: 00/00/0000
A9: 15/04/2025 | B9: OFFICER S. A. DISTRIBUIDORA DE PRODUTOS DE TECNOLOGIA | C9: SERVIÇOS ADVOCATÍCIOS | D9: 17000 | E9: 0 | F9: 17000 | G9: 22669.77 | H9: 00/00/0000
A10: 15/05/2025 | B10: OFFICER S. A. DISTRIBUIDORA DE PRODUTOS DE TECNOLOGIA | C10: SERVIÇOS ADVOCATÍCIOS | D10: 17000 | E10: 0 | F10: 17000 | G10: 22399.05 | H10: 00/00/0000
A11: 15/06/2025 | B11: OFFICER S. A. DISTRIBUIDORA DE PRODUTOS DE TECNOLOGIA | C11: SERVIÇOS ADVOCATÍCIOS | D11: 17000 | E11: 0 | F11: 17000 | G11: 22145.71 | H11: 00/00/0000
A12: 15/07/2025 | B12: OFFICER S. A. DISTRIBUIDORA DE PRODUTOS DE TECNOLOGIA | C12: SERVIÇOS ADVOCATÍCIOS | D12: 17000 | E12: 0 | F12: 17000 | G12: 21915.7 | H12: 00/00/0000
A13: 12/08/2025 | B13: OFFICER S. A. DISTRIBUIDORA DE PRODUTOS DE TECNOLOGIA | C13: SERVIÇOS ADVOCATÍCIOS | D13: 10000 | E13: 0 | F13: 10000 | G13: 12748.01 | H13: 00/00/0000
A14: 15/08/2025 | B14: OFFICER S. A. DISTRIBUIDORA DE PRODUTOS DE TECNOLOGIA | C14: SERVIÇOS ADVOCATÍCIOS | D14: 17000 | E14: 0 | F14: 17000 | G14: 21671.62 | H14: 00/00/0000
... A24: 15/01/2026 | B24: OFFICER S. A. DISTRIBUIDORA DE PRODUTOS DE TECNOLOGIA | C24: SERVIÇOS ADVOCATÍCIOS | D24: 17000 | E24: 0 | F24: 17000 | G24: 20611.14 | H24: 00/00/0000
F25: =SUM(F3:F24) -> 324921.25 | G25: =SUM(G3:G24) -> 422863.68
A27: 17/11/2025 | B27: Luciano Kubrusly | C27: SERVIÇOS ADVOCATÍCIOS | D27: 4500 | E27: 0 | F27: 4500 | G27: 5571.05 | H27: 00/00/0000
A28: 17/12/2025 | B28: Luciano Kubrusly | C28: SERVIÇOS ADVOCATÍCIOS | D28: 4500 | E28: 0 | F28: 4500 | G28: 5514.73 | H28: 00/00/0000
A29: 09/01/2026 | B29: Luciano Kubrusly | C29: SERVIÇOS ADVOCATÍCIOS | D29: 5000 | E29: 0 | F29: 5000 | G29: 6062.1 | H29: 00/00/0000
A30: 17/01/2026 | B30: Luciano Kubrusly | C30: SERVIÇOS ADVOCATÍCIOS | D30: 4500 | E30: 0 | F30: 4500 | G30: 5455.89 | H30: 00/00/0000
A31: 46062 | B31: Luciano Kubrusly | C31: SERVIÇOS ADVOCATÍCIOS | D31: 5000 | E31: 0 | F31: =D31-E31 -> 5000
F32: =SUM(F27:F31) -> 23500 | G32: =SUM(G27:G30) -> 22603.77
E34: Total grupo | F34: =F25+F32 -> 348421.25 | G34: =G25+G32 -> 445467.45

Sheet PRISCILLA ROSSETTI
A2: Data Vencimento | B2: Cliente | C2: Descrição | D2: Valor Faturado | E2: Valor Pago | F2: Valor em Aberto | G2: Data Baixa
A3: 11/05/2025 | B3: Priscilla dos Santos Rosseti | C3: SERVIÇOS ADVOCATÍCIOS | D3: 650 | E3: 0 | F3: 650 | G3: 00/00/0000
A4: 11/06/2025 | B4: Priscilla dos Santos Rosseti | C4: SERVIÇOS ADVOCATÍCIOS | D4: 650 | E4: 0 | F4: 650 | G4: 00/00/0000
A5: 11/07/2025 | B5: Priscilla dos Santos Rosseti | C5: SERVIÇOS ADVOCATÍCIOS | D5: 650 | E5: 0 | F5: 650 | G5: 00/00/0000
A6: 11/08/2025 | B6: Priscilla dos Santos Rosseti | C6: SERVIÇOS ADVOCATICIOS | D6: 650 | E6: 0 | F6: 650 | G6: 00/00/0000
A7: 11/09/2025 | B7: Priscilla dos Santos Rosseti | C7: SERVIÇOS ADVOCATICIOS | D7: 650 | E7: 0 | F7: 650 | G7: 00/00/0000
A8: 11/10/2025 | B8: Priscilla dos Santos Rosseti | C8: SERVIÇOS ADVOCATICIOS | D8: 650 | E8: 0 | F8: 650 | G8: 00/00/0000
A9: 11/11/2025 | B9: Priscilla dos Santos Rosseti | C9: SERVIÇOS ADVOCATICIOS | D9: 650 | E9: 0 | F9: 650 | G9: 00/00/0000
A10: 11/12/2025 | B10: Priscilla dos Santos Rosseti | C10: SERVIÇOS ADVOCATICIOS | D10: 650 | E10: 0 | F10: 650 | G10: 00/00/0000
A11: 11/01/2026 | B11: Priscilla dos Santos Rosseti | C11: SERVIÇOS ADVOCATÍCIOS | D11: 650 | E11: 0 | F11: 650 | G11: 00/00/0000
F12: =SUM(F3:F11) -> 5850

Sheet RCG
A2: Data Vencimento | B2: Cliente | C2: Descrição | D2: Valor Faturado | E2: Valor Pago | F2: Valor em Aberto | G2: Data Baixa
A3: 25/01/2025 | B3: Rcg Tecnologia Eletromecanica Ltda - Em Recuperacao Judicial | C3: SERVIÇOS ADVOCATÍCIOS | D3: 11700 | E3: 928.35 | F3: 10771.65 | G3: 00/00/0000
A4: 25/02/2025 | B4: Rcg Tecnologia Eletromecanica Ltda - Em Recuperacao Judicial | C4: SERVIÇOS ADVOCATÍCIOS | D4: 11700 | E4: 0 | F4: 11700 | G4: 00/00/0000
A5: 25/03/2025 | B5: Rcg Tecnologia Eletromecanica Ltda - Em Recuperacao Judicial | C5: SERVIÇOS ADVOCATÍCIOS | D5: 11700 | E5: 0 | F5: 11700 | G5: 00/00/0000
A6: 25/04/2025 | B6: Rcg Tecnologia Eletromecanica Ltda - Em Recuperacao Judicial | C6: SERVIÇOS ADVOCATÍCIOS | D6: 11700 | E6: 0 | F6: 11700 | G6: 00/00/0000
A7: 25/05/2025 | B7: Rcg Tecnologia Eletromecanica Ltda - Em Recuperacao Judicial | C7: SERVIÇOS ADVOCATÍCIOS | D7: 11700 | E7: 0 | F7: 11700 | G7: 00/00/0000
A8: 25/06/2025 | B8: Rcg Tecnologia Eletromecanica Ltda - Em Recuperacao Judicial | C8: SERVIÇOS ADVOCATÍCIOS | D8: 11700 | E8: 0 | F8: 11700 | G8: 00/00/0000
A9: 25/07/2025 | B9: Rcg Tecnologia Eletromecanica Ltda - Em Recuperacao Judicial | C9: SERVIÇOS ADVOCATÍCIOS | D9: 11700 | E9: 0 | F9: 11700 | G9: 00/00/0000
A10: 25/08/2025 | B10: Rcg Tecnologia Eletromecanica Ltda - Em Recuperacao Judicial | C10: SERVIÇOS ADVOCATÍCIOS | D10: 11700 | E10: 0 | F10: 11700 | G10: 00/00/0000
A11: 25/09/2025 | B11: Rcg Tecnologia Eletromecanica Ltda - Em Recuperacao Judicial | C11: SERVIÇOS ADVOCATÍCIOS | D11: 11700 | E11: 0 | F11: 11700 | G11: 00/00/0000
A12: 25/10/2025 | B12: Rcg Tecnologia Eletromecanica Ltda - Em Recuperacao Judicial | C12: SERVIÇOS ADVOCATÍCIOS | D12: 11700 | E12: 0 | F12: 11700 | G12: 00/00/0000
A13: 25/11/2025 | B13: Rcg Tecnologia Eletromecanica Ltda - Em Recuperacao Judicial | C13: SERVIÇOS ADVOCATÍCIOS | D13: 11700 | E13: 0 | F13: 11700 | G13: 00/00/0000
A14: 25/12/2025 | B14: Rcg Tecnologia Eletromecanica Ltda - Em Recuperacao Judicial | C14: SERVIÇOS ADVOCATÍCIOS | D14: 11700 | E14: 0 | F14: 11700 | G14: 00/00/0000
A15: 25/01/2026 | B15: Rcg Tecnologia Eletromecanica Ltda - Em Recuperacao Judicial | C15: SERVIÇOS ADVOCATÍCIOS | D15: 11700 | E15: 0 | F15: 11700 | G15: 00/00/0000
F16: =SUM(F3:F15) -> 151171.65

Sheet SPEL
A2: Data Vencimento | B2: Cliente | C2: Descrição | D2: Valor Faturado | E2: Valor Pago | F2: Valor em Aberto | G2: Data Baixa
A3: 15/07/2025 | B3: Spel Embalagens Ltda | C3: SERVIÇOS ADVOCATÍCIOS | D3: 20000 | E3: 0 | F3: 14154.84 | G3: 00/00/0000
