Workbook

Sheet Leia-me
A1: Tópico | B1: Conteúdo
A2: O que é este arquivo | B2: Configuração e classificação da Fase 2. Nada aqui é o indicador final. Os limiares de materialidade estão em branco para você preencher.
A3: Período | B3: 2026-01 a 2026-08. Agosto é o último mês fechado em 23/09/2026. Edite em Configuracao; os números desta geração usam esse recorte.
A4: Regime | B4: Eixo = competência (competencia_titulo, valor do item). Caixa (data_pagamento, valor pago) entra na conciliação. Os dois estão calculados.
A5: Referência 2026 | B5: Não é orçamento aprovado. Referência montada em jul/2026 a partir do realizado até ago. Aba Referencia_2026.
A6: Sócios de capital | B6: Pró-labore 8.1.03, contas nominais de sócios e distribuição de lucros ficam FORA do OPEX, na linha Remuneração de sócios de capital, abaixo do resultado operacional. Associados (8.1.01) e sócios de serviço permanecem em Pessoas.
A7: Reembolso | B7: PAGAR com departamento Conta Corrente Clientes sai do OPEX. Custas 5.6.02, 2.6.01, 2.6.01.005, 2.6.03, 5.16.06 e 5.16.07 em qualquer outro departamento ficam no OPEX, grupo Despesas Processuais, com flag.
A8: Repasse | B8: 2.6.04.000 está fora do OPEX e não teve movimento no período. O repasse efetivo está em 3.2.07.000 (REPASSE DE OUTRAS RECEITAS), também fora. A entrada correspondente no RECEBER está documentada na aba Repasse.
A9: Tributos | B9: DAS 2.2.06.002, DARF 2.2.06.001, ISS 3.3.01.000, ISSQN 2.2.06.003 e Tributos 2.2.06.000 saem do OPEX. No período essas contas estão zeradas, exceto ISS (R$ 209,13). O DAS, o parcelamento do Simples e o PGFN foram lançados na 5.14.03 e saíram do OPEX com status sugerida e flag composição pendente. Anuidade e demais linhas da 5.14.03 permanecem no OPEX, com flag para revisão.
A10: Financeiras | B10: 5.18.01, 5.18.02, 5.18.04 e 5.18.05 ficam no OPEX (Administrativo e Financeiro / Custos bancários e de cobrança). 5.18.03 multas e juros fica fora.
A11: Como editar | B11: Na aba Lancamentos, preencha override_dentro_opex ou override_recorrente. A coluna final e a Reconciliacao em fórmula acompanham o override. A classificação sugerida está na aba Classificacao_contas.
A12: Materialidade | B12: Um item só é material se o valor E o percentual sobre o OPEX de competência atingirem os dois limiares. Enquanto estiverem vazios, a coluna fica "aguardando limiar".
... A14: 13º e férias | B14: provisionar_13_ferias = sim. A aba Provisao_13_ferias mostra o lançado e uma provisão sugerida (soma do período / 8). A base não é folha individual, porque o cadastro não tem custo por pessoa.

Sheet Configuracao
A1: parametro | B1: valor | C1: opcoes_ou_nota
A2: periodo_inicio | B2: 2026-01 | C2: editável
A3: periodo_fim | B3: 2026-08 | C3: último mês fechado em 23/09/2026
A4: regime_eixo | B4: competencia | C4: competencia | caixa
A5: regime_conciliacao | B5: caixa | C5: o outro regime, para bater caixa e competência
A6: calcular_ambos | B6: sim | C6: os dois regimes estão nas colunas valor_competencia e valor_caixa
A7: receita_referencia | B7: liquida_faturada | C7: liquida_faturada (eficiência) | recebida (só leitura de caixa)
A8: tratamento_socios | B8: fora_do_opex | C8: fora_do_opex | dentro_do_opex
A9: limiar_materialidade_valor | C9: R$. Preencher. Item material só se valor E percentual passarem.
A10: limiar_materialidade_pct | C10: Percentual sobre o OPEX de competência do período. Ex.: 1 para 1%.
A11: peso_fte_estagiario | B11: 0.75 | C11: usado na aba Pessoas_fte
A12: meses_run_rate | B12: 3 | C12: parâmetro para a fase de cálculo; ainda não aplicado a um indicador
A13: provisionar_13_ferias | B13: sim | C13: ver aba Provisao_13_ferias
A14: nome_orcamento | B14: Referência 2026 | C14: não é orçamento aprovado
A15: nota_orcamento | B15: referência montada em jul/2026 a partir do realizado até ago | C15: usar este texto em qualquer saída

Sheet Exclusoes
A1: regra | B1: chave | C1: efeito | D1: destino | E1: status | F1: nota
A2: departamento | B2: Conta Corrente Clientes | C2: fora do OPEX | D2: Despesas reembolsáveis de clientes | E2: confirmada | F2: Vale para qualquer conta PAGAR nesse departamento.
A3: conta | B3: 2.6.04.000 | C3: fora do OPEX | D3: Repasse ao cliente | E3: confirmada | F3: Sem movimento em jan–ago/2026.
A4: conta | B4: 3.2.07.000 | C4: fora do OPEX | D4: Repasse ao cliente | E4: confirmada | F4: É a conta que carrega o repasse no período.
A5: conta | B5: 8.1.03.000 | C5: fora do OPEX | D5: Remuneração de sócios de capital | E5: confirmada | F5: Pró-labore = sócio de capital.
A6: conta | B6: 2.4.01.000 | C6: fora do OPEX | D6: Remuneração de sócios de capital | E6: confirmada | F6: Conta nominal Ricardo Pires.
A7: conta | B7: 2.4.02.000 | C7: fora do OPEX | D7: Remuneração de sócios de capital | E7: confirmada | F7: Conta nominal Gustavo Bismarchi.
A8: conta | B8: 7.1.01.000 | C8: fora do OPEX | D8: Remuneração de sócios de capital | E8: confirmada | F8: Distribuição de lucros.
A9: conta | B9: 7.1.02.000 | C9: fora do OPEX | D9: Remuneração de sócios de capital | E9: confirmada | F9: Dividendos parcelas fixas.
A10: prefixo | B10: 10. | C10: fora do OPEX | D10: Investimento / CAPEX | E10: confirmada
A11: prefixo | B11: 3.4 | C11: fora do OPEX | D11: Deduções da receita | E11: confirmada | F11: Devolução de honorários.
A12: conta | B12: 2.2.06.002 | C12: fora do OPEX | D12: Deduções / tributos sobre faturamento | E12: confirmada | F12: DAS. Flag composição pendente.
A13: conta | B13: 2.2.06.001 | C13: fora do OPEX | D13: Deduções / tributos sobre faturamento | E13: confirmada | F13: DARF. Flag composição pendente.
A14: conta | B14: 3.3.01.000 | C14: fora do OPEX | D14: Deduções / tributos sobre faturamento | E14: confirmada | F14: ISS. Flag composição pendente.
A15: conta | B15: 2.2.06.003 | C15: fora do OPEX | D15: Deduções / tributos sobre faturamento | E15: confirmada | F15: ISSQN. Flag composição pendente.
A16: conta | B16: 2.2.06.000 | C16: fora do OPEX | D16: Deduções / tributos sobre faturamento | E16: confirmada | F16: Tributos da sede. Flag composição pendente. Sem movimento no período.
A17: descrição na conta de impostos | B17: DAS, DARF, ISSQN, Simples Nacional, parcelamento PGFN | C17: fora do OPEX | D17: Deduções / tributos sobre faturamento | E17: sugerida | F17: No período isso está na 5.14.03, não nas contas 2.2.06. Anuidade da mesma conta permanece no OPEX.
A18: conta | B18: 5.18.03.000 | C18: fora do OPEX | D18: Multas e juros | E18: confirmada
A19: prefixo | B19: 1.1.02 / 1.1.03 / 1.1.08 | C19: fora do OPEX | D19: Adiantamento ou transferência | E19: sugerida | F19: Não é despesa operacional. Entra na reconciliação como excluído.
A20: conta | B20: 5.6.02 / 2.6.01 / 2.6.01.005 / 2.6.03 / 5.16.06 / 5.16.07 | C20: dentro do OPEX | D20: Despesas Processuais | E20: confirmada | F20: Só quando o departamento NÃO é Conta Corrente Clientes. Flag processual_possivelmente_reembolsavel.
A21: conta | B21: 4.1.01 / 4.1.02 / 2.3.07 | C21: dentro do OPEX | D21: Comissões | E21: confirmada | F21: Natureza variável.
A22: conta | B22: 5.18.01 / 5.18.02 / 5.18.04 / 5.18.05 | C22: dentro do OPEX | D22: Administrativo e Financeiro | E22: confirmada | F22: Subgrupo Custos bancários e de cobrança. 5.18.05 = tarifas de boleto.
A23: receita | B23: RECEBER + Conta Corrente Clientes + REEMBOLSO DE DESPESAS | C23: fora da receita | D23: Reembolso de despesas | E23: confirmada | F23: Não entra na receita de referência.

Sheet Classificacao_contas
A1: conta_numero | B1: plano_contas | C1: grupo_conta | D1: dentro_opex | E1: status_perimetro | F1: motivo_perimetro | G1: grupo_gerencial | H1: subgrupo | I1: natureza | J1: controlabilidade | K1: tipo | L1: potencial_eficiencia | M1: status_classificacao | N1: flag | O1: qtd_lancamentos | P1: valor_competencia | Q1: valor_caixa | R1: pct_opex_competencia
A2: 8.1.01.000 | B2: HONORÁRIOS ASSOCIADOS | C2: REMUNERAÇãO FIXA | D2: sim | E2: confirmada | G2: Pessoas | H2: Associados | I2: fixa | J2: contratual | K2: despesa | L2: médio | M2: sugerida | O2: 394 | P2: 2275610.7 | Q2: 2540065 | R2: 0.51271007
A3: 7.1.01.000 | B3: DISTRIBUIÇãO DE LUCROS | C3: DISTRIBUIÇãO DE LUCROS | D3: não | E3: confirmada | F3: Remuneração de sócios de capital | G3: Remuneração de sócios de capital | H3: Remuneração de sócios de capital | I3: — | J3: — | K3: exclusão | L3: não avaliado | M3: confirmada | N3: abaixo_do_resultado_operacional | O3: 274 | P3: 1782959.5 | Q3: 1783854.4 | R3: 0
A4: 8.1.03.000 | B4: PRÓ-LABORE | C4: REMUNERAÇãO FIXA | D4: não | E4: confirmada | F4: Remuneração de sócios de capital | G4: Remuneração de sócios de capital | H4: Remuneração de sócios de capital | I4: — | J4: — | K4: exclusão | L4: não avaliado | M4: confirmada | N4: abaixo_do_resultado_operacional | O4: 39 | P4: 942000 | Q4: 942000 | R4: 0
A5: 3.2.07.000 | B5: REPASSE DE OUTRAS RECEITAS | C5: OUTRAS RECEITAS OPERACIONAIS | D5: não | E5: confirmada | F5: Repasse ao cliente (3.2.07 REPASSE DE OUTRAS RECEITAS; 2.6.04 sem movimento no período) | G5: Repasse ao cliente | H5: Repasse ao cliente (3.2.07 REPASSE DE OUTRAS RECEITAS; 2.6.04 sem movimento no período) | I5: — | J5: — | K5: exclusão | L5: não avaliado | M5: confirmada | N5: repasse | O5: 53 | P5: 835346.5 | Q5: 856695.8 | R5: 0
A6: 5.14.03.000 | B6: IMPOSTOS E TAXAS | C6: IMPOSTOS, TAXAS E SEGUROS | D6: não | E6: sugerida | F6: Deduções / tributos sobre faturamento | G6: Deduções / tributos sobre faturamento | H6: Deduções / tributos sobre faturamento | I6: — | J6: — | K6: exclusão | L6: não avaliado | M6: sugerida | N6: composicao_pendente;lancado_em_5.14.03.000_descricao_DAS_parcelamento | O6: 24 | P6: 543014.18 | Q6: 543014.18 | R6: 0
A7: 5.8.20.000 | B7: CONSULTORIA | C7: DESPESAS COM SERVIÇOS DE TERCEIROS | D7: sim | E7: confirmada | G7: Serviços Terceirizados | H7: Serviços de terceiros | I7: semivariável | J7: contratual | K7: despesa | L7: alto | M7: sugerida | O7: 52 | P7: 252652.93 | Q7: 252324.42 | R7: 0.056924368
A8: 3.2.07.000 | B8: REPASSE DE OUTRAS RECEITAS | C8: OUTRAS RECEITAS OPERACIONAIS | D8: não | E8: confirmada | F8: Despesas reembolsáveis de clientes | G8: Despesas reembolsáveis de clientes | H8: Despesas reembolsáveis de clientes | I8: — | J8: — | K8: exclusão | L8: não avaliado | M8: confirmada | N8: departamento_conta_corrente_clientes | O8: 3 | P8: 233028.81 | Q8: 233028.81 | R8: 0
A9: 5.13.01.000 | B9: ALUGUEL DE IMÓVEL | C9: ALUGUÉIS | D9: sim | E9: confirmada | G9: Ocupação/Facilities | H9: Aluguel | I9: fixa | J9: contratual | K9: despesa | L9: baixo | M9: sugerida | O9: 8 | P9: 214683.01 | Q9: 214683.01 | R9: 0.048369495
A10: 4.1.02.000 | B10: COMISSÕES INTERNAS | C10: COMISSÕES SOBRE VENDAS | D10: sim | E10: confirmada | G10: Comissões | H10: Comissões | I10: variável | J10: decisão interna | K10: despesa | L10: médio | M10: confirmada | O10: 203 | P10: 186194.49 | Q10: 186194.49 | R10: 0.041950844
A11: 9.1.05.000 | B11: SISTEMAS DE GESTÃO E OPERAÇãO | C11: TECNOLOGIA E SISTEMAS | D11: sim | E11: confirmada | G11: Tecnologia e Sistemas | H11: Sistemas e informática | I11: fixa | J11: contratual | K11: despesa | L11: médio | M11: sugerida | O11: 138 | P11: 175058.93 | Q11: 174758.93 | R11: 0.039441929
A12: 8.1.02.000 | B12: SALÁRIOS | C12: REMUNERAÇãO FIXA | D12: sim | E12: confirmada | G12: Pessoas | H12: CLT | I12: fixa | J12: contratual | K12: despesa | L12: médio | M12: sugerida | O12: 42 | P12: 131038.27 | Q12: 144306.91 | R12: 0.029523785
A13: 8.3.02.000 | B13: INSS | C13: ENCARGOS SOCIAIS | D13: sim | E13: confirmada | G13: Pessoas | H13: Encargos | I13: fixa | J13: obrigação legal | K13: despesa | L13: baixo | M13: sugerida | O13: 69 | P13: 130481.44 | Q13: 130481.44 | R13: 0.029398327
A14: 4.1.01.000 | B14: COMISSÕES PARCEIROS | C14: COMISSÕES SOBRE VENDAS | D14: sim | E14: confirmada | G14: Comissões | H14: Comissões | I14: variável | J14: decisão interna | K14: despesa | L14: médio | M14: confirmada | O14: 168 | P14: 116219.95 | Q14: 102231.71 | R14: 0.02618512
A15: 8.3.03.000 | B15: IRRF | C15: ENCARGOS SOCIAIS | D15: sim | E15: confirmada | G15: Pessoas | H15: Encargos | I15: fixa | J15: obrigação legal | K15: despesa | L15: baixo | M15: sugerida | O15: 20 | P15: 99529.22 | Q15: 99529.22 | R15: 0.022424588
A16: 8.2.01.000 | B16: BÔNUS | C16: REMUNERAÇãO VARIÁVEL | D16: sim | E16: confirmada | G16: Pessoas | H16: Bônus | I16: variável | J16: decisão interna | K16: despesa | L16: médio | M16: sugerida | O16: 40 | P16: 86908.01 | Q16: 90908.01 | R16: 0.019580947
A17: 5.15.05.000 | B17: PATROCÍNIOS | C17: PROPAGANDA E MARKETING | D17: sim | E17: confirmada | G17: Marketing e Desenvolvimento de Negócios | H17: Marketing | I17: variável | J17: decisão interna | K17: despesa | L17: alto | M17: sugerida | O17: 10 | P17: 75626.66 | Q17: 75626.66 | R17: 0.017039184
A18: 8.5.04.000 | B18: EVENTOS | C18: TREINAMENTO/DESENVOLVIMENTO/CULTURA | D18: sim | E18: confirmada | G18: Pessoas | H18: Treinamento | I18: variável | J18: decisão interna | K18: despesa | L18: alto | M18: sugerida | O18: 50 | P18: 63534.2 | Q18: 53534.2 | R18: 0.014314673
A19: 7.1.02.000 | B19: DIVIDENDOS PARCELAS FIXAS | C19: DISTRIBUIÇãO DE LUCROS | D19: não | E19: confirmada | F19: Remuneração de sócios de capital | G19: Remuneração de sócios de capital | H19: Remuneração de sócios de capital | I19: — | J19: — | K19: exclusão | L19: não avaliado | M19: confirmada | N19: abaixo_do_resultado_operacional | O19: 15 | P19: 44000 | Q19: 44000 | R19: 0
A20: 8.4.03.000 | B20: ASSISTÊNCIA MÉDICA E ODONTOLÓGICA | C20: BENEFÍCIOS | D20: sim | E20: confirmada | G20: Pessoas | H20: Benefícios | I20: fixa | J20: contratual | K20: despesa | L20: médio | M20: sugerida | O20: 27 | P20: 37079.71 | Q20: 37079.71 | R20: 0.0083543027
A21: 8.7.04.000 | B21: SALDO REMUNERAÇãO ASSOCIADOS | C21: DESLIGAMENTOS | D21: sim | E21: confirmada | G21: Pessoas | H21: Desligamentos | I21: variável | J21: obrigação legal | K21: despesa | L21: baixo | M21: sugerida | O21: 12 | P21: 29808.02 | Q21: 29808.02 | R21: 0.0067159431
A22: 9.1.03.000 | B22: MARKETING E COMERCIAL | C22: TECNOLOGIA E SISTEMAS | D22: sim | E22: confirmada | G22: Marketing e Desenvolvimento de Negócios | H22: Marketing | I22: variável | J22: decisão interna | K22: despesa | L22: alto | M22: sugerida | O22: 22 | P22: 29746.04 | Q22: 29746.04 | R22: 0.0067019786
A23: 8.4.01.000 | B23: VALE REFEIÇãO/VALE ALIMENTAÇãO | C23: BENEFÍCIOS | D23: sim | E23: confirmada | G23: Pessoas | H23: Benefícios | I23: fixa | J23: contratual | K23: despesa | L23: médio | M23: sugerida | O23: 27 | P23: 29502 | Q23: 29502 | R23: 0.0066469947
A24: 5.14.03.000 | B24: IMPOSTOS E TAXAS | C24: IMPOSTOS, TAXAS E SEGUROS | D24: sim | E24: confirmada | G24: Ocupação/Facilities | H24: Taxas e seguros do escritório | I24: fixa | J24: obrigação legal | K24: despesa | L24: baixo | M24: sugerida | N24: revisar_se_e_tributo_sobre_faturamento | O24: 35 | P24: 28496.41 | Q24: 26994.69 | R24: 0.0064204287
A25: 5.8.19.000 | B25: HONORÁRIOS CONTÁBEIS | C25: DESPESAS COM SERVIÇOS DE TERCEIROS | D25: sim | E25: confirmada | G25: Serviços Terceirizados | H25: Serviços de terceiros | I25: semivariável | J25: contratual | K25: despesa | L25: alto | M25: sugerida | O25: 13 | P25: 27753.2 | Q25: 27753.2 | R25: 0.0062529786
A26: 5.16.06.000 | B26: OUTRAS DESPESAS REEMBOLSÁVEIS | C26: OUTRAS DESPESAS | D26: não | E26: confirmada | F26: Despesas reembolsáveis de clientes | G26: Despesas reembolsáveis de clientes | H26: Despesas reembolsáveis de clientes | I26: — | J26: — | K26: exclusão | L26: não avaliado | M26: confirmada | N26: departamento_conta_corrente_clientes | O26: 70 | P26: 26902.35 | Q26: 26902.35 | R26: 0
A27: 8.4.06.000 | B27: ESTACIONAMENTO | C27: BENEFÍCIOS | D27: sim | E27: confirmada | G27: Pessoas | H27: Benefícios | I27: fixa | J27: contratual | K27: despesa | L27: médio | M27: sugerida | O27: 45 | P27: 26400 | Q27: 24359.99 | R27: 0.0059480937
A28: 5.8.02.000 | B28: SERVIÇOS DE INFORMÁTICA | C28: DESPESAS COM SERVIÇOS DE TERCEIROS | D28: sim | E28: confirmada | G28: Tecnologia e Sistemas | H28: Sistemas e informática | I28: fixa | J28: contratual | K28: despesa | L28: médio | M28: sugerida | O28: 13 | P28: 25368.56 | Q28: 25368.56 | R28: 0.0057157035
A29: 1.1.02.000 | B29: ADIANTAMENTOS | C29: SAÍDAS - EMPRÉSTIMOS APL. E DEVOLUÇÕES | D29: não | E29: confirmada | F29: Despesas reembolsáveis de clientes | G29: Despesas reembolsáveis de clientes | H29: Despesas reembolsáveis de clientes | I29: — | J29: — | K29: exclusão | L29: não avaliado | M29: confirmada | N29: departamento_conta_corrente_clientes | O29: 9 | P29: 25024.67 | Q29: 25024.67 | R29: 0
A30: 8.7.06.000 | B30: SALDO DE FÉRIAS ASSOCIADOS | C30: DESLIGAMENTOS | D30: sim | E30: confirmada | G30: Pessoas | H30: 13º e férias | I30: semivariável | J30: obrigação legal | K30: despesa | L30: baixo | M30: sugerida | O30: 3 | P30: 22135.82 | Q30: 22135.82 | R30: 0.0049873459
A31: 5.8.07.000 | B31: GRÁFICA | C31: DESPESAS COM SERVIÇOS DE TERCEIROS | D31: sim | E31: confirmada | G31: Serviços Terceirizados | H31: Serviços de terceiros | I31: semivariável | J31: contratual | K31: despesa | L31: alto | M31: sugerida | O31: 15 | P31: 21084.99 | Q31: 17155 | R31: 0.004750587
A32: 8.4.05.000 | B32: AUXÍLIO EDUCACIONAL | C32: BENEFÍCIOS | D32: sim | E32: confirmada | G32: Pessoas | H32: Benefícios | I32: fixa | J32: contratual | K32: despesa | L32: médio | M32: sugerida | O32: 28 | P32: 21048.28 | Q32: 21048.28 | R32: 0.004742316
A33: 5.15.06.000 | B33: SERVIÇOS FOTOGRÁFICOS / FILMAGEM | C33: PROPAGANDA E MARKETING | D33: sim | E33: confirmada | G33: Marketing e Desenvolvimento de Negócios | H33: Marketing | I33: variável | J33: decisão interna | K33: despesa | L33: alto | M33: sugerida | O33: 8 | P33: 20000 | Q33: 20000 | R33: 0.0045061316
A34: 8.5.05.000 | B34: DATAS COMEMORATIVAS | C34: TREINAMENTO/DESENVOLVIMENTO/CULTURA | D34: sim | E34: confirmada | G34: Pessoas | H34: Treinamento | I34: variável | J34: decisão interna | K34: despesa | L34: alto | M34: sugerida | O34: 25 | P34: 19584.27 | Q34: 19584.27 | R34: 0.0044124649
A35: 5.9.03.000 | B35: MANUTENÇãO PREDIAL | C35: DESPESAS DE MANUTENÇãO | D35: sim | E35: confirmada | G35: Ocupação/Facilities | H35: Manutenção | I35: semivariável | J35: decisão interna | K35: despesa | L35: médio | M35: sugerida | O35: 41 | P35: 19189.04 | Q35: 19039.04 | R35: 0.004323417
A36: 5.6.02.000 | B36: CUSTAS JUDICIAIS | C36: ASSOCIAÇÕES E CUSTAS JUDICIAIS | D36: sim | E36: confirmada | G36: Despesas Processuais | H36: Custas e despesas processuais | I36: variável | J36: obrigação legal | K36: despesa | L36: baixo | M36: confirmada | N36: processual_possivelmente_reembolsavel | O36: 51 | P36: 19024.49 | Q36: 19024.49 | R36: 0.0042863428
A37: 1.1.08.000 | B37: DEVOLUÇãO DE ADIANTAMENTOS DE CLIENTES | C37: SAÍDAS - EMPRÉSTIMOS APL. E DEVOLUÇÕES | D37: não | E37: confirmada | F37: Despesas reembolsáveis de clientes | G37: Despesas reembolsáveis de clientes | H37: Despesas reembolsáveis de clientes | I37: — | J37: — | K37: exclusão | L37: não avaliado | M37: confirmada | N37: departamento_conta_corrente_clientes | O37: 2 | P37: 18024.88 | Q37: 18024.88 | R37: 0
A38: 5.16.09.000 | B38: PERMUTAS | C38: OUTRAS DESPESAS | D38: sim | E38: confirmada | G38: Administrativo Geral | H38: PERMUTAS | I38: semivariável | J38: decisão interna | K38: despesa | L38: médio | M38: sugerida | O38: 1 | P38: 18000 | Q38: 18000 | R38: 0.0040555185
A39: 5.10.01.000 | B39: MATERIAL DE HIGIENE E LIMPEZA | C39: MATERIAL DE CONSUMO, LIMPEZA E SEGURANÇA | D39: sim | E39: confirmada | G39: Ocupação/Facilities | H39: Copa, limpeza e consumo | I39: semivariável | J39: decisão interna | K39: despesa | L39: médio | M39: sugerida | O39: 58 | P39: 15368.78 | Q39: 13767.41 | R39: 0.0034626873
A40: 8.3.01.000 | B40: FGTS | C40: ENCARGOS SOCIAIS | D40: sim | E40: confirmada | G40: Pessoas | H40: Encargos | I40: fixa | J40: obrigação legal | K40: despesa | L40: baixo | M40: sugerida | O40: 27 | P40: 14872.08 | Q40: 14872.08 | R40: 0.0033507775
...

Sheet Lancamentos
A1: ci_item | B1: nro_titulo | C1: descricao | D1: fornecedor | E1: departamento | F1: grupo_conta | G1: plano_contas | H1: conta_numero | I1: mes_competencia | J1: mes_pagamento | K1: valor_competencia | L1: valor_caixa | M1: dentro_opex_regra | N1: status_perimetro | O1: motivo_perimetro | P1: flag | Q1: grupo_gerencial | R1: subgrupo | S1: natureza | T1: controlabilidade | U1: tipo | V1: potencial_eficiencia | W1: status_classificacao | X1: recorrente_sugerido | Y1: motivo_recorrencia | Z1: status_recorrencia | AA1: override_dentro_opex | AB1: override_recorrente | AC1: dentro_opex_final | AD1: recorrente_final | AE1: material
A2: 15960 | C2: DEVOLUÇÃO ADIANTAMENTO | D2: Nigro Aluminio Ltda | E2: Conta Corrente Clientes | F2: SAÍDAS - EMPRÉSTIMOS APL. E DEVOLUÇÕES | G2: ADIANTAMENTOS | H2: 1.1.02.000 | I2: 2026-03 | J2: 2026-03 | K2: 2.55 | L2: 2.55 | M2: não | N2: confirmada | O2: Despesas reembolsáveis de clientes | P2: departamento_conta_corrente_clientes | Q2: Despesas reembolsáveis de clientes | R2: Despesas reembolsáveis de clientes | S2: — | T2: — | U2: exclusão | V2: não avaliado | W2: confirmada | X2: sim | Z2: sem sinal | AC2: =IF(AA2="",M2,AA2) -> não | AD2: =IF(AB2="",X2,AB2) -> sim | AE2: =IF(OR(Configuracao!B9="",Configuracao!B10=""),"aguardando limiar",IF(AND(K2>=Configuracao!B9,K2/MAX(Reconciliacao!C2,1)>=Configuracao!B10/100),"sim","não")) -> aguardando limiar
A3: 12930 | C3: CUSTAS NIGRO | D3: Caio Augusto de Alcantara Cesar Silva | E3: Conta Corrente Clientes | F3: SAÍDAS - EMPRÉSTIMOS APL. E DEVOLUÇÕES | G3: ADIANTAMENTOS | H3: 1.1.02.000 | I3: 2026-02 | J3: 2026-02 | K3: 40 | L3: 40 | M3: não | N3: confirmada | O3: Despesas reembolsáveis de clientes | P3: departamento_conta_corrente_clientes | Q3: Despesas reembolsáveis de clientes | R3: Despesas reembolsáveis de clientes | S3: — | T3: — | U3: exclusão | V3: não avaliado | W3: confirmada | X3: sim | Z3: sem sinal | AC3: =IF(AA3="",M3,AA3) -> não | AD3: =IF(AB3="",X3,AB3) -> sim | AE3: =IF(OR(Configuracao!B9="",Configuracao!B10=""),"aguardando limiar",IF(AND(K3>=Configuracao!B9,K3/MAX(Reconciliacao!C2,1)>=Configuracao!B10/100),"sim","não")) -> aguardando limiar
A4: 15959 | C4: DEVOLUÇÃO ADIANTAMENTO | D4: Carvalho Assessoria Empreendimentos Imobiliarios Ltda | E4: Conta Corrente Clientes | F4: SAÍDAS - EMPRÉSTIMOS APL. E DEVOLUÇÕES | G4: ADIANTAMENTOS | H4: 1.1.02.000 | I4: 2026-03 | J4: 2026-03 | K4: 44 | L4: 44 | M4: não | N4: confirmada | O4: Despesas reembolsáveis de clientes | P4: departamento_conta_corrente_clientes | Q4: Despesas reembolsáveis de clientes | R4: Despesas reembolsáveis de clientes | S4: — | T4: — | U4: exclusão | V4: não avaliado | W4: confirmada | X4: sim | Z4: sem sinal | AC4: =IF(AA4="",M4,AA4) -> não | AD4: =IF(AB4="",X4,AB4) -> sim | AE4: =IF(OR(Configuracao!B9="",Configuracao!B10=""),"aguardando limiar",IF(AND(K4>=Configuracao!B9,K4/MAX(Reconciliacao!C2,1)>=Configuracao!B10/100),"sim","não")) -> aguardando limiar
A5: 13040 | C5: CUSTAS CARVALHO | D5: Caio Augusto de Alcantara Cesar Silva | E5: Conta Corrente Clientes | F5: SAÍDAS - EMPRÉSTIMOS APL. E DEVOLUÇÕES | G5: ADIANTAMENTOS | H5: 1.1.02.000 | I5: 2026-02 | J5: 2026-02 | K5: 56.75 | L5: 56.75 | M5: não | N5: confirmada | O5: Despesas reembolsáveis de clientes | P5: departamento_conta_corrente_clientes | Q5: Despesas reembolsáveis de clientes | R5: Despesas reembolsáveis de clientes | S5: — | T5: — | U5: exclusão | V5: não avaliado | W5: confirmada | X5: sim | Z5: sem sinal | AC5: =IF(AA5="",M5,AA5) -> não | AD5: =IF(AB5="",X5,AB5) -> sim | AE5: =IF(OR(Configuracao!B9="",Configuracao!B10=""),"aguardando limiar",IF(AND(K5>=Configuracao!B9,K5/MAX(Reconciliacao!C2,1)>=Configuracao!B10/100),"sim","não")) -> aguardando limiar
A6: 13360 | C6: DEVOLUÇÃO ADIANTAMENTO CUSTAS | D6: Spel Embalagens Ltda | E6: Conta Corrente Clientes | F6: SAÍDAS - EMPRÉSTIMOS APL. E DEVOLUÇÕES | G6: ADIANTAMENTOS | H6: 1.1.02.000 | I6: 2026-03 | J6: 2026-03 | K6: 166 | L6: 166 | M6: não | N6: confirmada | O6: Despesas reembolsáveis de clientes | P6: departamento_conta_corrente_clientes | Q6: Despesas reembolsáveis de clientes | R6: Despesas reembolsáveis de clientes | S6: — | T6: — | U6: exclusão | V6: não avaliado | W6: confirmada | X6: sim | Z6: sem sinal | AC6: =IF(AA6="",M6,AA6) -> não | AD6: =IF(AB6="",X6,AB6) -> sim | AE6: =IF(OR(Configuracao!B9="",Configuracao!B10=""),"aguardando limiar",IF(AND(K6>=Configuracao!B9,K6/MAX(Reconciliacao!C2,1)>=Configuracao!B10/100),"sim","não")) -> aguardando limiar
A7: 12782 | C7: CUSTAS SUSTENTARE | D7: Fernanda Andrade Camolesi | E7: Conta Corrente Clientes | F7: SAÍDAS - EMPRÉSTIMOS APL. E DEVOLUÇÕES | G7: ADIANTAMENTOS | H7: 1.1.02.000 | I7: 2026-03 | J7: 2026-03 | K7: 250 | L7: 250 | M7: não | N7: confirmada | O7: Despesas reembolsáveis de clientes | P7: departamento_conta_corrente_clientes | Q7: Despesas reembolsáveis de clientes | R7: Despesas reembolsáveis de clientes | S7: — | T7: — | U7: exclusão | V7: não avaliado | W7: confirmada | X7: sim | Z7: sem sinal | AC7: =IF(AA7="",M7,AA7) -> não | AD7: =IF(AB7="",X7,AB7) -> sim | AE7: =IF(OR(Configuracao!B9="",Configuracao!B10=""),"aguardando limiar",IF(AND(K7>=Configuracao!B9,K7/MAX(Reconciliacao!C2,1)>=Configuracao!B10/100),"sim","não")) -> aguardando limiar
A8: 12899 | C8: CORREIOS SPEL | D8: Laura Puente Ferreira Gomes | E8: Conta Corrente Clientes | F8: SAÍDAS - EMPRÉSTIMOS APL. E DEVOLUÇÕES | G8: ADIANTAMENTOS | H8: 1.1.02.000 | I8: 2026-03 | J8: 2026-03 | K8: 2294.95 | L8: 2294.95 | M8: não | N8: confirmada | O8: Despesas reembolsáveis de clientes | P8: departamento_conta_corrente_clientes | Q8: Despesas reembolsáveis de clientes | R8: Despesas reembolsáveis de clientes | S8: — | T8: — | U8: exclusão | V8: não avaliado | W8: confirmada | X8: não | Y8: fornecedor sem outra ocorrência na conta em 12 meses; valor atípico (acima de 3x a mediana da conta em 12 meses, mediana 166) | Z8: sugerido | AC8: =IF(AA8="",M8,AA8) -> não | AD8: =IF(AB8="",X8,AB8) -> não | AE8: =IF(OR(Configuracao!B9="",Configuracao!B10=""),"aguardando limiar",IF(AND(K8>=Configuracao!B9,K8/MAX(Reconciliacao!C2,1)>=Configuracao!B10/100),"sim","não")) -> aguardando limiar
A9: 13049 | C9: IPVA 2026 (CARRO GUSTAVO QUE FICA COM A IRMÃ. ADIANTOU O VALOR INTEGRAL E PAGAMOS NO MESMO DIA) | D9: SECRETARIA DE ESTADO DA FAZENDA | E9: Conta Corrente Clientes | F9: SAÍDAS - EMPRÉSTIMOS APL. E DEVOLUÇÕES | G9: ADIANTAMENTOS | H9: 1.1.02.000 | I9: 2026-02 | J9: 2026-02 | K9: 2348.73 | L9: 2348.73 | M9: não | N9: confirmada | O9: Despesas reembolsáveis de clientes | P9: departamento_conta_corrente_clientes | Q9: Despesas reembolsáveis de clientes | R9: Despesas reembolsáveis de clientes | S9: — | T9: — | U9: exclusão | V9: não avaliado | W9: confirmada | X9: não | Y9: fornecedor sem outra ocorrência na conta em 12 meses; valor atípico (acima de 3x a mediana da conta em 12 meses, mediana 166) | Z9: sugerido | AC9: =IF(AA9="",M9,AA9) -> não | AD9: =IF(AB9="",X9,AB9) -> não | AE9: =IF(OR(Configuracao!B9="",Configuracao!B10=""),"aguardando limiar",IF(AND(K9>=Configuracao!B9,K9/MAX(Reconciliacao!C2,1)>=Configuracao!B10/100),"sim","não")) -> aguardando limiar
A10: 17980 | C10: VALOR REF. REMUNERAÇÃO PAGO INDEVIDAMENTE - VALOR DEVOLVIDO NO DIA SEGUINTE | D10: Michel Donizeti de Medeiros Malaquias | E10: Conta Corrente Clientes | F10: SAÍDAS - EMPRÉSTIMOS APL. E DEVOLUÇÕES | G10: ADIANTAMENTOS | H10: 1.1.02.000 | I10: 2026-07 | J10: 2026-07 | K10: 19821.69 | L10: 19821.69 | M10: não | N10: confirmada | O10: Despesas reembolsáveis de clientes | P10: departamento_conta_corrente_clientes | Q10: Despesas reembolsáveis de clientes | R10: Despesas reembolsáveis de clientes | S10: — | T10: — | U10: exclusão | V10: não avaliado | W10: confirmada | X10: não | Y10: fornecedor sem outra ocorrência na conta em 12 meses; valor atípico (acima de 3x a mediana da conta em 12 meses, mediana 166) | Z10: sugerido | AC10: =IF(AA10="",M10,AA10) -> não | AD10: =IF(AB10="",X10,AB10) -> não | AE10: =IF(OR(Configuracao!B9="",Configuracao!B10=""),"aguardando limiar",IF(AND(K10>=Configuracao!B9,K10/MAX(Reconciliacao!C2,1)>=Configuracao!B10/100),"sim","não")) -> aguardando limiar
A11: 17696 | C11: DEVOLUÇÃO VALOR PAGO INDEVIDAMENTE JUNTO COM ND | D11: Macan Logistica e Transportes Ltda | E11: Conta Corrente Clientes | F11: SAÍDAS - EMPRÉSTIMOS APL. E DEVOLUÇÕES | G11: DEVOLUÇãO DE ADIANTAMENTOS DE CLIENTES | H11: 1.1.08.000 | I11: 2026-06 | J11: 2026-06 | K11: 24.88 | L11: 24.88 | M11: não | N11: confirmada | O11: Despesas reembolsáveis de clientes | P11: departamento_conta_corrente_clientes | Q11: Despesas reembolsáveis de clientes | R11: Despesas reembolsáveis de clientes | S11: — | T11: — | U11: exclusão | V11: não avaliado | W11: confirmada | X11: sim | Z11: sem sinal | AC11: =IF(AA11="",M11,AA11) -> não | AD11: =IF(AB11="",X11,AB11) -> sim | AE11: =IF(OR(Configuracao!B9="",Configuracao!B10=""),"aguardando limiar",IF(AND(K11>=Configuracao!B9,K11/MAX(Reconciliacao!C2,1)>=Configuracao!B10/100),"sim","não")) -> aguardando limiar
A12: 12932 | C12: DEVOLUÇÃO HONORÁRIO PAGO INDEVIDAMENTE (DEZ/25 E JAN/26) | D12: Primi & Appoloni Arquitetura Ltda. | E12: Trabalhista | F12: SAÍDAS - EMPRÉSTIMOS APL. E DEVOLUÇÕES | G12: DEVOLUÇãO DE ADIANTAMENTOS DE CLIENTES | H12: 1.1.08.000 | I12: 2026-02 | J12: 2026-02 | K12: 7600 | L12: 7600 | M12: não | N12: sugerida | O12: Adiantamento ou transferência (não é despesa operacional) | Q12: Fora do OPEX | R12: Adiantamento ou transferência (não é despesa operacional) | S12: — | T12: — | U12: exclusão | V12: não avaliado | W12: sugerida | X12: não | Y12: fornecedor sem outra ocorrência na conta em 12 meses; valor atípico (acima de 3x a mediana da conta em 12 meses, mediana 28.05) | Z12: sugerido | AC12: =IF(AA12="",M12,AA12) -> não | AD12: =IF(AB12="",X12,AB12) -> não | AE12: =IF(OR(Configuracao!B9="",Configuracao!B10=""),"aguardando limiar",IF(AND(K12>=Configuracao!B9,K12/MAX(Reconciliacao!C2,1)>=Configuracao!B10/100),"sim","não")) -> aguardando limiar
A13: 11995 | C13: DEVOLUÇÃO VALOR RECEBIDO EQUIVOCADAMENTE | D13: Bárbara Stefany Minosso Menezes | E13: Conta Corrente Clientes | F13: SAÍDAS - EMPRÉSTIMOS APL. E DEVOLUÇÕES | G13: DEVOLUÇãO DE ADIANTAMENTOS DE CLIENTES | H13: 1.1.08.000 | I13: 2026-01 | J13: 2026-01 | K13: 18000 | L13: 18000 | M13: não | N13: confirmada | O13: Despesas reembolsáveis de clientes | P13: departamento_conta_corrente_clientes | Q13: Despesas reembolsáveis de clientes | R13: Despesas reembolsáveis de clientes | S13: — | T13: — | U13: exclusão | V13: não avaliado | W13: confirmada | X13: não | Y13: fornecedor sem outra ocorrência na conta em 12 meses; valor atípico (acima de 3x a mediana da conta em 12 meses, mediana 28.05) | Z13: sugerido | AC13: =IF(AA13="",M13,AA13) -> não | AD13: =IF(AB13="",X13,AB13) -> não | AE13: =IF(OR(Configuracao!B9="",Configuracao!B10=""),"aguardando limiar",IF(AND(K13>=Configuracao!B9,K13/MAX(Reconciliacao!C2,1)>=Configuracao!B10/100),"sim","não")) -> aguardando limiar
A14: 12135 | C14: CAIXA DE SOM PORTÁTIL | D14: Mercado Livre | E14: Facilities | F14: INVESTIMENTOS | G14: MÓVEIS E EQUIPAMENTOS | H14: 10.1.01.000 | I14: 2026-02 | J14: 2026-02 | K14: 112.66 | L14: 112.66 | M14: não | N14: confirmada | O14: Investimento / CAPEX | Q14: Investimento / CAPEX | R14: Investimento / CAPEX | S14: — | T14: — | U14: investimento | V14: não avaliado | W14: confirmada | X14: sim | Z14: sem sinal | AC14: =IF(AA14="",M14,AA14) -> não | AD14: =IF(AB14="",X14,AB14) -> sim | AE14: =IF(OR(Configuracao!B9="",Configuracao!B10=""),"aguardando limiar",IF(AND(K14>=Configuracao!B9,K14/MAX(Reconciliacao!C2,1)>=Configuracao!B10/100),"sim","não")) -> aguardando limiar
A15: 15817 | C15: MÁQUINA DOLCE GUSTO | D15: NESTLE BRASIL LTDA. | E15: Facilities | F15: INVESTIMENTOS | G15: MÓVEIS E EQUIPAMENTOS | H15: 10.1.01.000 | I15: 2026-04 | J15: 2026-04 | K15: 454.77 | L15: 454.77 | M15: não | N15: confirmada | O15: Investimento / CAPEX | Q15: Investimento / CAPEX | R15: Investimento / CAPEX | S15: — | T15: — | U15: investimento | V15: não avaliado | W15: confirmada | X15: sim | Z15: sem sinal | AC15: =IF(AA15="",M15,AA15) -> não | AD15: =IF(AB15="",X15,AB15) -> sim | AE15: =IF(OR(Configuracao!B9="",Configuracao!B10=""),"aguardando limiar",IF(AND(K15>=Configuracao!B9,K15/MAX(Reconciliacao!C2,1)>=Configuracao!B10/100),"sim","não")) -> aguardando limiar
A16: 18519 | C16: MONITOR - VALENTINA | D16: Magazine Luiza Marketplace | E16: Marketing | F16: INVESTIMENTOS | G16: EQUIPAMENTOS DE INFORMÁTICA | H16: 10.1.03.000 | I16: 2026-07 | J16: 2026-07 | K16: 209.14 | L16: 209.14 | M16: não | N16: confirmada | O16: Investimento / CAPEX | Q16: Investimento / CAPEX | R16: Investimento / CAPEX | S16: — | T16: — | U16: investimento | V16: não avaliado | W16: confirmada | X16: sim | Z16: sem sinal | AC16: =IF(AA16="",M16,AA16) -> não | AD16: =IF(AB16="",X16,AB16) -> sim | AE16: =IF(OR(Configuracao!B9="",Configuracao!B10=""),"aguardando limiar",IF(AND(K16>=Configuracao!B9,K16/MAX(Reconciliacao!C2,1)>=Configuracao!B10/100),"sim","não")) -> aguardando limiar
A17: 19029 | C17: MONITOR - CATHARINA CARDOSO | D17: Magazine Luiza Marketplace | E17: R.H. | F17: INVESTIMENTOS | G17: EQUIPAMENTOS DE INFORMÁTICA | H17: 10.1.03.000 | I17: 2026-08 | J17: 2026-09 | K17: 219.88 | L17: 0 | M17: não | N17: confirmada | O17: Investimento / CAPEX | Q17: Investimento / CAPEX | R17: Investimento / CAPEX | S17: — | T17: — | U17: investimento | V17: não avaliado | W17: confirmada | X17: sim | Z17: sem sinal | AC17: =IF(AA17="",M17,AA17) -> não | AD17: =IF(AB17="",X17,AB17) -> sim | AE17: =IF(OR(Configuracao!B9="",Configuracao!B10=""),"aguardando limiar",IF(AND(K17>=Configuracao!B9,K17/MAX(Reconciliacao!C2,1)>=Configuracao!B10/100),"sim","não")) -> aguardando limiar
A18: 12071 | C18: TABLET PARA PONTO ELETRÔNICO | D18: Mercado Livre | E18: Facilities | F18: INVESTIMENTOS | G18: EQUIPAMENTOS DE INFORMÁTICA | H18: 10.1.03.000 | I18: 2026-04 | J18: 2026-04 | K18: 326.66 | L18: 326.66 | M18: não | N18: confirmada | O18: Investimento / CAPEX | Q18: Investimento / CAPEX | R18: Investimento / CAPEX | S18: — | T18: — | U18: investimento | V18: não avaliado | W18: confirmada | X18: sim | Z18: sem sinal | AC18: =IF(AA18="",M18,AA18) -> não | AD18: =IF(AB18="",X18,AB18) -> sim | AE18: =IF(OR(Configuracao!B9="",Configuracao!B10=""),"aguardando limiar",IF(AND(K18>=Configuracao!B9,K18/MAX(Reconciliacao!C2,1)>=Configuracao!B10/100),"sim","não")) -> aguardando limiar
A19: 12072 | C19: TABLET PARA PONTO ELETRÔNICO | D19: Mercado Livre | E19: Facilities | F19: INVESTIMENTOS | G19: EQUIPAMENTOS DE INFORMÁTICA | H19: 10.1.03.000 | I19: 2026-05 | J19: 2026-05 | K19: 326.66 | L19: 326.66 | M19: não | N19: confirmada | O19: Investimento / CAPEX | Q19: Investimento / CAPEX | R19: Investimento / CAPEX | S19: — | T19: — | U19: investimento | V19: não avaliado | W19: confirmada | X19: sim | Z19: sem sinal | AC19: =IF(AA19="",M19,AA19) -> não | AD19: =IF(AB19="",X19,AB19) -> sim | AE19: =IF(OR(Configuracao!B9="",Configuracao!B10=""),"aguardando limiar",IF(AND(K19>=Configuracao!B9,K19/MAX(Reconciliacao!C2,1)>=Configuracao!B10/100),"sim","não")) -> aguardando limiar
A20: 12070 | C20: TABLET PARA PONTO ELETRÔNICO | D20: Mercado Livre | E20: Facilities | F20: INVESTIMENTOS | G20: EQUIPAMENTOS DE INFORMÁTICA | H20: 10.1.03.000 | I20: 2026-03 | J20: 2026-03 | K20: 326.68 | L20: 326.68 | M20: não | N20: confirmada | O20: Investimento / CAPEX | Q20: Investimento / CAPEX | R20: Investimento / CAPEX | S20: — | T20: — | U20: investimento | V20: não avaliado | W20: confirmada | X20: sim | Z20: sem sinal | AC20: =IF(AA20="",M20,AA20) -> não | AD20: =IF(AB20="",X20,AB20) -> sim | AE20: =IF(OR(Configuracao!B9="",Configuracao!B10=""),"aguardando limiar",IF(AND(K20>=Configuracao!B9,K20/MAX(Reconciliacao!C2,1)>=Configuracao!B10/100),"sim","não")) -> aguardando limiar
A21: 12832 | C21: NOTEBOOK - LEONARDO MARQUES | D21: Amazon Servicos | E21: Marketing | F21: INVESTIMENTOS | G21: EQUIPAMENTOS DE INFORMÁTICA | H21: 10.1.03.000 | I21: 2026-04 | J21: 2026-04 | K21: 555.9 | L21: 555.9 | M21: não | N21: confirmada | O21: Investimento / CAPEX | Q21: Investimento / CAPEX | R21: Investimento / CAPEX | S21: — | T21: — | U21: investimento | V21: não avaliado | W21: confirmada | X21: sim | Z21: sem sinal | AC21: =IF(AA21="",M21,AA21) -> não | AD21: =IF(AB21="",X21,AB21) -> sim | AE21: =IF(OR(Configuracao!B9="",Configuracao!B10=""),"aguardando limiar",IF(AND(K21>=Configuracao!B9,K21/MAX(Reconciliacao!C2,1)>=Configuracao!B10/100),"sim","não")) -> aguardando limiar
A22: 12833 | C22: NOTEBOOK - LEONARDO MARQUES | D22: Amazon Servicos | E22: Marketing | F22: INVESTIMENTOS | G22: EQUIPAMENTOS DE INFORMÁTICA | H22: 10.1.03.000 | I22: 2026-05 | J22: 2026-05 | K22: 555.9 | L22: 555.9 | M22: não | N22: confirmada | O22: Investimento / CAPEX | Q22: Investimento / CAPEX | R22: Investimento / CAPEX | S22: — | T22: — | U22: investimento | V22: não avaliado | W22: confirmada | X22: sim | Z22: sem sinal | AC22: =IF(AA22="",M22,AA22) -> não | AD22: =IF(AB22="",X22,AB22) -> sim | AE22: =IF(OR(Configuracao!B9="",Configuracao!B10=""),"aguardando limiar",IF(AND(K22>=Configuracao!B9,K22/MAX(Reconciliacao!C2,1)>=Configuracao!B10/100),"sim","não")) -> aguardando limiar
A23: 12834 | C23: NOTEBOOK - LEONARDO MARQUES | D23: Amazon Servicos | E23: Marketing | F23: INVESTIMENTOS | G23: EQUIPAMENTOS DE INFORMÁTICA | H23: 10.1.03.000 | I23: 2026-06 | J23: 2026-06 | K23: 555.9 | L23: 555.9 | M23: não | N23: confirmada | O23: Investimento / CAPEX | Q23: Investimento / CAPEX | R23: Investimento / CAPEX | S23: — | T23: — | U23: investimento | V23: não avaliado | W23: confirmada | X23: sim | Z23: sem sinal | AC23: =IF(AA23="",M23,AA23) -> não | AD23: =IF(AB23="",X23,AB23) -> sim | AE23: =IF(OR(Configuracao!B9="",Configuracao!B10=""),"aguardando limiar",IF(AND(K23>=Configuracao!B9,K23/MAX(Reconciliacao!C2,1)>=Configuracao!B10/100),"sim","não")) -> aguardando limiar
A24: 12835 | C24: NOTEBOOK - LEONARDO MARQUES | D24: Amazon Servicos | E24: Marketing | F24: INVESTIMENTOS | G24: EQUIPAMENTOS DE INFORMÁTICA | H24: 10.1.03.000 | I24: 2026-07 | J24: 2026-07 | K24: 555.9 | L24: 555.9 | M24: não | N24: confirmada | O24: Investimento / CAPEX | Q24: Investimento / CAPEX | R24: Investimento / CAPEX | S24: — | T24: — | U24: investimento | V24: não avaliado | W24: confirmada | X24: sim | Z24: sem sinal | AC24: =IF(AA24="",M24,AA24) -> não | AD24: =IF(AB24="",X24,AB24) -> sim | AE24: =IF(OR(Configuracao!B9="",Configuracao!B10=""),"aguardando limiar",IF(AND(K24>=Configuracao!B9,K24/MAX(Reconciliacao!C2,1)>=Configuracao!B10/100),"sim","não")) -> aguardando limiar
A25: 12836 | C25: NOTEBOOK - LEONARDO MARQUES | D25: Amazon Servicos | E25: Marketing | F25: INVESTIMENTOS | G25: EQUIPAMENTOS DE INFORMÁTICA | H25: 10.1.03.000 | I25: 2026-08 | J25: 2026-08 | K25: 555.9 | L25: 555.9 | M25: não | N25: confirmada | O25: Investimento / CAPEX | Q25: Investimento / CAPEX | R25: Investimento / CAPEX | S25: — | T25: — | U25: investimento | V25: não avaliado | W25: confirmada | X25: sim | Z25: sem sinal | AC25: =IF(AA25="",M25,AA25) -> não | AD25: =IF(AB25="",X25,AB25) -> sim | AE25: =IF(OR(Configuracao!B9="",Configuracao!B10=""),"aguardando limiar",IF(AND(K25>=Configuracao!B9,K25/MAX(Reconciliacao!C2,1)>=Configuracao!B10/100),"sim","não")) -> aguardando limiar
A26: 17621 | C26: NOTEBOOK VINICIUS SCHMOCKEL | D26: Magazine Luiza Marketplace | E26: Operações Legais | F26: INVESTIMENTOS | G26: EQUIPAMENTOS DE INFORMÁTICA | H26: 10.1.03.000 | I26: 2026-06 | J26: 2026-06 | K26: 649.9 | L26: 649.9 | M26: não | N26: confirmada | O26: Investimento / CAPEX | Q26: Investimento / CAPEX | R26: Investimento / CAPEX | S26: — | T26: — | U26: investimento | V26: não avaliado | W26: confirmada | X26: sim | Z26: sem sinal | AC26: =IF(AA26="",M26,AA26) -> não | AD26: =IF(AB26="",X26,AB26) -> sim | AE26: =IF(OR(Configuracao!B9="",Configuracao!B10=""),"aguardando limiar",IF(AND(K26>=Configuracao!B9,K26/MAX(Reconciliacao!C2,1)>=Configuracao!B10/100),"sim","não")) -> aguardando limiar
A27: 17622 | C27: NOTEBOOK VINICIUS SCHMOCKEL | D27: Magazine Luiza Marketplace | E27: Operações Legais | F27: INVESTIMENTOS | G27: EQUIPAMENTOS DE INFORMÁTICA | H27: 10.1.03.000 | I27: 2026-07 | J27: 2026-07 | K27: 649.9 | L27: 649.9 | M27: não | N27: confirmada | O27: Investimento / CAPEX | Q27: Investimento / CAPEX | R27: Investimento / CAPEX | S27: — | T27: — | U27: investimento | V27: não avaliado | W27: confirmada | X27: sim | Z27: sem sinal | AC27: =IF(AA27="",M27,AA27) -> não | AD27: =IF(AB27="",X27,AB27) -> sim | AE27: =IF(OR(Configuracao!B9="",Configuracao!B10=""),"aguardando limiar",IF(AND(K27>=Configuracao!B9,K27/MAX(Reconciliacao!C2,1)>=Configuracao!B10/100),"sim","não")) -> aguardando limiar
A28: 17623 | C28: NOTEBOOK VINICIUS SCHMOCKEL | D28: Magazine Luiza Marketplace | E28: Operações Legais | F28: INVESTIMENTOS | G28: EQUIPAMENTOS DE INFORMÁTICA | H28: 10.1.03.000 | I28: 2026-08 | J28: 2026-08 | K28: 649.9 | L28: 649.9 | M28: não | N28: confirmada | O28: Investimento / CAPEX | Q28: Investimento / CAPEX | R28: Investimento / CAPEX | S28: — | T28: — | U28: investimento | V28: não avaliado | W28: confirmada | X28: sim | Z28: sem sinal | AC28: =IF(AA28="",M28,AA28) -> não | AD28: =IF(AB28="",X28,AB28) -> sim | AE28: =IF(OR(Configuracao!B9="",Configuracao!B10=""),"aguardando limiar",IF(AND(K28>=Configuracao!B9,K28/MAX(Reconciliacao!C2,1)>=Configuracao!B10/100),"sim","não")) -> aguardando limiar
A29: 9284 | C29: PARCELA 05/06 | D29: Magazine Luiza Marketplace | E29: Insolvência | F29: INVESTIMENTOS | G29: EQUIPAMENTOS DE INFORMÁTICA | H29: 10.1.03.000 | I29: 2026-01 | J29: 2026-01 | K29: 666.48 | L29: 666.48 | M29: não | N29: confirmada | O29: Investimento / CAPEX | Q29: Investimento / CAPEX | R29: Investimento / CAPEX | S29: — | T29: — | U29: investimento | V29: não avaliado | W29: confirmada | X29: sim | Z29: sem sinal | AC29: =IF(AA29="",M29,AA29) -> não | AD29: =IF(AB29="",X29,AB29) -> sim | AE29: =IF(OR(Configuracao!B9="",Configuracao!B10=""),"aguardando limiar",IF(AND(K29>=Configuracao!B9,K29/MAX(Reconciliacao!C2,1)>=Configuracao!B10/100),"sim","não")) -> aguardando limiar
A30: 9285 | C30: PARCELA 06/06 | D30: Magazine Luiza Marketplace | E30: Insolvência | F30: INVESTIMENTOS | G30: EQUIPAMENTOS DE INFORMÁTICA | H30: 10.1.03.000 | I30: 2026-02 | J30: 2026-02 | K30: 666.48 | L30: 666.48 | M30: não | N30: confirmada | O30: Investimento / CAPEX | Q30: Investimento / CAPEX | R30: Investimento / CAPEX | S30: — | T30: — | U30: investimento | V30: não avaliado | W30: confirmada | X30: sim | Z30: sem sinal | AC30: =IF(AA30="",M30,AA30) -> não | AD30: =IF(AB30="",X30,AB30) -> sim | AE30: =IF(OR(Configuracao!B9="",Configuracao!B10=""),"aguardando limiar",IF(AND(K30>=Configuracao!B9,K30/MAX(Reconciliacao!C2,1)>=Configuracao!B10/100),"sim","não")) -> aguardando limiar
A31: 11646 | C31: COMPRA NOTEBOOK QUE ESTAVA COM PAGAMENTO PENDENTE PELO RICARDO.NÃO HÁ RASTREIO SOBRE QUAL ÁREA UTILIZA O RESPECTIVO EQUIPAMENTO. | D31: Fabricio Fais Ferreira | E31: Ricardo Viscardi Pires | F31: INVESTIMENTOS | G31: EQUIPAMENTOS DE INFORMÁTICA | H31: 10.1.03.000 | I31: 2026-01 | J31: 2026-01 | K31: 1500 | L31: 1500 | M31: não | N31: confirmada | O31: Investimento / CAPEX | Q31: Investimento / CAPEX | R31: Investimento / CAPEX | S31: — | T31: — | U31: investimento | V31: não avaliado | W31: confirmada | X31: não | Y31: fornecedor sem outra ocorrência na conta em 12 meses | Z31: sugerido | AC31: =IF(AA31="",M31,AA31) -> não | AD31: =IF(AB31="",X31,AB31) -> não | AE31: =IF(OR(Configuracao!B9="",Configuracao!B10=""),"aguardando limiar",IF(AND(K31>=Configuracao!B9,K31/MAX(Reconciliacao!C2,1)>=Configuracao!B10/100),"sim","não")) -> aguardando limiar
A32: 12139 | C32: TELEFONE SALA GUSTAVO | D32: Amazon Servicos | E32: Gustavo Bismarchi Motta | F32: INVESTIMENTOS | G32: EQUIPAMENTOS DE COMUNICAÇãO | H32: 10.1.11.000 | I32: 2026-02 | J32: 2026-02 | K32: 189 | L32: 189 | M32: não | N32: confirmada | O32: Investimento / CAPEX | Q32: Investimento / CAPEX | R32: Investimento / CAPEX | S32: — | T32: — | U32: investimento | V32: não avaliado | W32: confirmada | X32: sim | Z32: sem sinal | AC32: =IF(AA32="",M32,AA32) -> não | AD32: =IF(AB32="",X32,AB32) -> sim | AE32: =IF(OR(Configuracao!B9="",Configuracao!B10=""),"aguardando limiar",IF(AND(K32>=Configuracao!B9,K32/MAX(Reconciliacao!C2,1)>=Configuracao!B10/100),"sim","não")) -> aguardando limiar
A33: 6001 | C33: REPASSE ACORDO CONSTRURBAN - PARCELA 15/15 | D33: Alexandre Fantazzini Rigi | E33: Distressed Deals | F33: OUTRAS RECEITAS OPERACIONAIS | G33: REPASSE DE OUTRAS RECEITAS | H33: 3.2.07.000 | I33: 2025-11 | J33: 2026-01 | K33: 0 | L33: 21349.3 | M33: não | N33: confirmada | O33: Repasse ao cliente (3.2.07 REPASSE DE OUTRAS RECEITAS; 2.6.04 sem movimento no período) | P33: repasse | Q33: Repasse ao cliente | R33: Repasse ao cliente (3.2.07 REPASSE DE OUTRAS RECEITAS; 2.6.04 sem movimento no período) | S33: — | T33: — | U33: exclusão | V33: não avaliado | W33: confirmada | X33: sim | Z33: sem sinal | AC33: =IF(AA33="",M33,AA33) -> não | AD33: =IF(AB33="",X33,AB33) -> sim | AE33: =IF(OR(Configuracao!B9="",Configuracao!B10=""),"aguardando limiar",IF(AND(K33>=Configuracao!B9,K33/MAX(Reconciliacao!C2,1)>=Configuracao!B10/100),"sim","não")) -> aguardando limiar
A34: 17019 | C34: REPASSE ACORDO CONSTRURBAN | D34: Alexandre Fantazzini Rigi | E34: Insolvência | F34: OUTRAS RECEITAS OPERACIONAIS | G34: REPASSE DE OUTRAS RECEITAS | H34: 3.2.07.000 | I34: 2026-06 | J34: 2026-06 | K34: 191.7 | L34: 191.7 | M34: não | N34: confirmada | O34: Repasse ao cliente (3.2.07 REPASSE DE OUTRAS RECEITAS; 2.6.04 sem movimento no período) | P34: repasse | Q34: Repasse ao cliente | R34: Repasse ao cliente (3.2.07 REPASSE DE OUTRAS RECEITAS; 2.6.04 sem movimento no período) | S34: — | T34: — | U34: exclusão | V34: não avaliado | W34: confirmada | X34: sim | Z34: sem sinal | AC34: =IF(AA34="",M34,AA34) -> não | AD34: =IF(AB34="",X34,AB34) -> sim | AE34: =IF(OR(Configuracao!B9="",Configuracao!B10=""),"aguardando limiar",IF(AND(K34>=Configuracao!B9,K34/MAX(Reconciliacao!C2,1)>=Configuracao!B10/100),"sim","não")) -> aguardando limiar
A35: 17833 | C35: REPASSE ACORDO CONSTRURBAN | D35: Alexandre Fantazzini Rigi | E35: Insolvência | F35: OUTRAS RECEITAS OPERACIONAIS | G35: REPASSE DE OUTRAS RECEITAS | H35: 3.2.07.000 | I35: 2026-07 | J35: 2026-07 | K35: 191.99 | L35: 191.99 | M35: não | N35: confirmada | O35: Repasse ao cliente (3.2.07 REPASSE DE OUTRAS RECEITAS; 2.6.04 sem movimento no período) | P35: repasse | Q35: Repasse ao cliente | R35: Repasse ao cliente (3.2.07 REPASSE DE OUTRAS RECEITAS; 2.6.04 sem movimento no período) | S35: — | T35: — | U35: exclusão | V35: não avaliado | W35: confirmada | X35: sim | Z35: sem sinal | AC35: =IF(AA35="",M35,AA35) -> não | AD35: =IF(AB35="",X35,AB35) -> sim | AE35: =IF(OR(Configuracao!B9="",Configuracao!B10=""),"aguardando limiar",IF(AND(K35>=Configuracao!B9,K35/MAX(Reconciliacao!C2,1)>=Configuracao!B10/100),"sim","não")) -> aguardando limiar
A36: 18691 | C36: REPASSE ACORDO CONSTRURBAN | D36: Alexandre Fantazzini Rigi | E36: Insolvência | F36: OUTRAS RECEITAS OPERACIONAIS | G36: REPASSE DE OUTRAS RECEITAS | H36: 3.2.07.000 | I36: 2026-08 | J36: 2026-08 | K36: 192.27 | L36: 192.27 | M36: não | N36: confirmada | O36: Repasse ao cliente (3.2.07 REPASSE DE OUTRAS RECEITAS; 2.6.04 sem movimento no período) | P36: repasse | Q36: Repasse ao cliente | R36: Repasse ao cliente (3.2.07 REPASSE DE OUTRAS RECEITAS; 2.6.04 sem movimento no período) | S36: — | T36: — | U36: exclusão | V36: não avaliado | W36: confirmada | X36: sim | Z36: sem sinal | AC36: =IF(AA36="",M36,AA36) -> não | AD36: =IF(AB36="",X36,AB36) -> sim | AE36: =IF(OR(Configuracao!B9="",Configuracao!B10=""),"aguardando limiar",IF(AND(K36>=Configuracao!B9,K36/MAX(Reconciliacao!C2,1)>=Configuracao!B10/100),"sim","não")) -> aguardando limiar
A37: 13358 | C37: REPASSE ACORDO DECORWATTS X PENA CONSTRUÇÕES | D37: Decorwatts Eletrica e Iluminacao Ltda | E37: Distressed Deals | F37: OUTRAS RECEITAS OPERACIONAIS | G37: REPASSE DE OUTRAS RECEITAS | H37: 3.2.07.000 | I37: 2026-03 | J37: 2026-03 | K37: 302.49 | L37: 302.49 | M37: não | N37: confirmada | O37: Repasse ao cliente (3.2.07 REPASSE DE OUTRAS RECEITAS; 2.6.04 sem movimento no período) | P37: repasse | Q37: Repasse ao cliente | R37: Repasse ao cliente (3.2.07 REPASSE DE OUTRAS RECEITAS; 2.6.04 sem movimento no período) | S37: — | T37: — | U37: exclusão | V37: não avaliado | W37: confirmada | X37: sim | Z37: sem sinal | AC37: =IF(AA37="",M37,AA37) -> não | AD37: =IF(AB37="",X37,AB37) -> sim | AE37: =IF(OR(Configuracao!B9="",Configuracao!B10=""),"aguardando limiar",IF(AND(K37>=Configuracao!B9,K37/MAX(Reconciliacao!C2,1)>=Configuracao!B10/100),"sim","não")) -> aguardando limiar
A38: 13359 | C38: REPASSE ACORDO DECORWATTS X KM 18 | D38: Decorwatts Eletrica e Iluminacao Ltda | E38: Distressed Deals | F38: OUTRAS RECEITAS OPERACIONAIS | G38: REPASSE DE OUTRAS RECEITAS | H38: 3.2.07.000 | I38: 2026-03 | J38: 2026-03 | K38: 312.41 | L38: 312.41 | M38: não | N38: confirmada | O38: Repasse ao cliente (3.2.07 REPASSE DE OUTRAS RECEITAS; 2.6.04 sem movimento no período) | P38: repasse | Q38: Repasse ao cliente | R38: Repasse ao cliente (3.2.07 REPASSE DE OUTRAS RECEITAS; 2.6.04 sem movimento no período) | S38: — | T38: — | U38: exclusão | V38: não avaliado | W38: confirmada | X38: sim | Z38: sem sinal | AC38: =IF(AA38="",M38,AA38) -> não | AD38: =IF(AB38="",X38,AB38) -> sim | AE38: =IF(OR(Configuracao!B9="",Configuracao!B10=""),"aguardando limiar",IF(AND(K38>=Configuracao!B9,K38/MAX(Reconciliacao!C2,1)>=Configuracao!B10/100),"sim","não")) -> aguardando limiar
A39: 12238 | C39: MLE PROCESSO 1000140-12.2020.8.26.0650 | D39: Perfilix Industria e Comercio de Perfis Eireli | E39: Conta Corrente Clientes | F39: OUTRAS RECEITAS OPERACIONAIS | G39: REPASSE DE OUTRAS RECEITAS | H39: 3.2.07.000 | I39: 2026-02 | J39: 2026-02 | K39: 314.01 | L39: 314.01 | M39: não | N39: confirmada | O39: Despesas reembolsáveis de clientes | P39: departamento_conta_corrente_clientes | Q39: Despesas reembolsáveis de clientes | R39: Despesas reembolsáveis de clientes | S39: — | T39: — | U39: exclusão | V39: não avaliado | W39: confirmada | X39: sim | Z39: sem sinal | AC39: =IF(AA39="",M39,AA39) -> não | AD39: =IF(AB39="",X39,AB39) -> sim | AE39: =IF(OR(Configuracao!B9="",Configuracao!B10=""),"aguardando limiar",IF(AND(K39>=Configuracao!B9,K39/MAX(Reconciliacao!C2,1)>=Configuracao!B10/100),"sim","não")) -> aguardando limiar
A40: 17330 | C40: REPASSE LIBERAÇÃO JUDICIAL PROC. 000306587020258160014REJANE COSTA - R$ 7.917,00EUNICE RENNA - R$ 16.000,00FATIMA SAMÕES - R$ 10.500,00FELIPE RODRIGUES - R$ 516,92FELIPE RODRIGUES - R$ 1.000,00LILIAN VIEIRA - R$ 2.000,00 | D40: Decorwatts Eletrica e Iluminacao Ltda | E40: Recuperação de Crédito | F40: OUTRAS RECEITAS OPERACIONAIS | G40: REPASSE DE OUTRAS RECEITAS | H40: 3.2.07.000 | I40: 2026-06 | J40: 2026-06 | K40: 516.92 | L40: 516.92 | M40: não | N40: confirmada | O40: Repasse ao cliente (3.2.07 REPASSE DE OUTRAS RECEITAS; 2.6.04 sem movimento no período) | P40: repasse | Q40: Repasse ao cliente | R40: Repasse ao cliente (3.2.07 REPASSE DE OUTRAS RECEITAS; 2.6.04 sem movimento no período) | S40: — | T40: — | U40: exclusão | V40: não avaliado | W40: confirmada | X40: sim | Z40: sem sinal | AC40: =IF(AA40="",M40,AA40) -> não | AD40: =IF(AB40="",X40,AB40) -> sim | AE40: =IF(OR(Configuracao!B9="",Configuracao!B10=""),"aguardando limiar",IF(AND(K40>=Configuracao!B9,K40/MAX(Reconciliacao!C2,1)>=Configuracao!B10/100),"sim","não")) -> aguardando limiar
...

Sheet Reconciliacao
A1: mes | B1: regime | C1: total_saidas | D1: opex | E1: excluidos | F1: opex_mais_excluidos | G1: diferenca | H1: bate
A2: 2026-01 a 2026-08 | B2: competencia_total_opex | C2: 4438396.8
A3: 2026-01 | B3: competencia | C3: =SUMIFS(Lancamentos!K$2:K$3028,Lancamentos!I$2:I$3028,A3) -> 652200.32 | D3: =SUMIFS(Lancamentos!K$2:K$3028,Lancamentos!I$2:I$3028,A3,Lancamentos!AC$2:AC$3028,"sim") -> 320693.36 | E3: =C3-D3 -> 331506.96 | F3: =D3+E3 -> 652200.32 | G3: =F3-C3 -> 0 | H3: =IF(ABS(G3)<0.05,"sim","não") -> sim
A4: 2026-01 | B4: caixa | C4: =SUMIFS(Lancamentos!L$2:L$3028,Lancamentos!J$2:J$3028,A4) -> 938756.48 | D4: =SUMIFS(Lancamentos!L$2:L$3028,Lancamentos!J$2:J$3028,A4,Lancamentos!AC$2:AC$3028,"sim") -> 585282.33 | E4: =C4-D4 -> 353474.15 | F4: =D4+E4 -> 938756.48 | G4: =F4-C4 -> 0 | H4: =IF(ABS(G4)<0.05,"sim","não") -> sim
A5: 2026-02 | B5: competencia | C5: =SUMIFS(Lancamentos!K$2:K$3028,Lancamentos!I$2:I$3028,A5) -> 1163641.2 | D5: =SUMIFS(Lancamentos!K$2:K$3028,Lancamentos!I$2:I$3028,A5,Lancamentos!AC$2:AC$3028,"sim") -> 810278.94 | E5: =C5-D5 -> 353362.31 | F5: =D5+E5 -> 1163641.2 | G5: =F5-C5 -> 0 | H5: =IF(ABS(G5)<0.05,"sim","não") -> sim
A6: 2026-02 | B6: caixa | C6: =SUMIFS(Lancamentos!L$2:L$3028,Lancamentos!J$2:J$3028,A6) -> 862622.25 | D6: =SUMIFS(Lancamentos!L$2:L$3028,Lancamentos!J$2:J$3028,A6,Lancamentos!AC$2:AC$3028,"sim") -> 509697.87 | E6: =C6-D6 -> 352924.38 | F6: =D6+E6 -> 862622.25 | G6: =F6-C6 -> 0 | H6: =IF(ABS(G6)<0.05,"sim","não") -> sim
A7: 2026-03 | B7: competencia | C7: =SUMIFS(Lancamentos!K$2:K$3028,Lancamentos!I$2:I$3028,A7) -> 1243292.8 | D7: =SUMIFS(Lancamentos!K$2:K$3028,Lancamentos!I$2:I$3028,A7,Lancamentos!AC$2:AC$3028,"sim") -> 610109.78 | E7: =C7-D7 -> 633183 | F7: =D7+E7 -> 1243292.8 | G7: =F7-C7 -> 0 | H7: =IF(ABS(G7)<0.05,"sim","não") -> sim
A8: 2026-03 | B8: caixa | C8: =SUMIFS(Lancamentos!L$2:L$3028,Lancamentos!J$2:J$3028,A8) -> 1201756.6 | D8: =SUMIFS(Lancamentos!L$2:L$3028,Lancamentos!J$2:J$3028,A8,Lancamentos!AC$2:AC$3028,"sim") -> 568135.69 | E8: =C8-D8 -> 633620.93 | F8: =D8+E8 -> 1201756.6 | G8: =F8-C8 -> 0 | H8: =IF(ABS(G8)<0.05,"sim","não") -> sim
A9: 2026-04 | B9: competencia | C9: =SUMIFS(Lancamentos!K$2:K$3028,Lancamentos!I$2:I$3028,A9) -> 1281104.5 | D9: =SUMIFS(Lancamentos!K$2:K$3028,Lancamentos!I$2:I$3028,A9,Lancamentos!AC$2:AC$3028,"sim") -> 598072.55 | E9: =C9-D9 -> 683031.97 | F9: =D9+E9 -> 1281104.5 | G9: =F9-C9 -> 0 | H9: =IF(ABS(G9)<0.05,"sim","não") -> sim
A10: 2026-04 | B10: caixa | C10: =SUMIFS(Lancamentos!L$2:L$3028,Lancamentos!J$2:J$3028,A10) -> 1280718.1 | D10: =SUMIFS(Lancamentos!L$2:L$3028,Lancamentos!J$2:J$3028,A10,Lancamentos!AC$2:AC$3028,"sim") -> 597686.18 | E10: =C10-D10 -> 683031.97 | F10: =D10+E10 -> 1280718.1 | G10: =F10-C10 -> 0 | H10: =IF(ABS(G10)<0.05,"sim","não") -> sim
A11: 2026-05 | B11: competencia | C11: =SUMIFS(Lancamentos!K$2:K$3028,Lancamentos!I$2:I$3028,A11) -> 1181725.4 | D11: =SUMIFS(Lancamentos!K$2:K$3028,Lancamentos!I$2:I$3028,A11,Lancamentos!AC$2:AC$3028,"sim") -> 592766.37 | E11: =C11-D11 -> 588959 | F11: =D11+E11 -> 1181725.4 | G11: =F11-C11 -> 0 | H11: =IF(ABS(G11)<0.05,"sim","não") -> sim
A12: 2026-05 | B12: caixa | C12: =SUMIFS(Lancamentos!L$2:L$3028,Lancamentos!J$2:J$3028,A12) -> 1170175.3 | D12: =SUMIFS(Lancamentos!L$2:L$3028,Lancamentos!J$2:J$3028,A12,Lancamentos!AC$2:AC$3028,"sim") -> 581216.3 | E12: =C12-D12 -> 588959 | F12: =D12+E12 -> 1170175.3 | G12: =F12-C12 -> 0 | H12: =IF(ABS(G12)<0.05,"sim","não") -> sim
A13: 2026-06 | B13: competencia | C13: =SUMIFS(Lancamentos!K$2:K$3028,Lancamentos!I$2:I$3028,A13) -> 1206702.6 | D13: =SUMIFS(Lancamentos!K$2:K$3028,Lancamentos!I$2:I$3028,A13,Lancamentos!AC$2:AC$3028,"sim") -> 594221.63 | E13: =C13-D13 -> 612480.92 | F13: =D13+E13 -> 1206702.6 | G13: =F13-C13 -> 0 | H13: =IF(ABS(G13)<0.05,"sim","não") -> sim
A14: 2026-06 | B14: caixa | C14: =SUMIFS(Lancamentos!L$2:L$3028,Lancamentos!J$2:J$3028,A14) -> 1215671.9 | D14: =SUMIFS(Lancamentos!L$2:L$3028,Lancamentos!J$2:J$3028,A14,Lancamentos!AC$2:AC$3028,"sim") -> 598643.97 | E14: =C14-D14 -> 617027.96 | F14: =D14+E14 -> 1215671.9 | G14: =F14-C14 -> 0 | H14: =IF(ABS(G14)<0.05,"sim","não") -> sim
A15: 2026-07 | B15: competencia | C15: =SUMIFS(Lancamentos!K$2:K$3028,Lancamentos!I$2:I$3028,A15) -> 1269958.4 | D15: =SUMIFS(Lancamentos!K$2:K$3028,Lancamentos!I$2:I$3028,A15,Lancamentos!AC$2:AC$3028,"sim") -> 610906.05 | E15: =C15-D15 -> 659052.37 | F15: =D15+E15 -> 1269958.4 | G15: =F15-C15 -> 0 | H15: =IF(ABS(G15)<0.05,"sim","não") -> sim
A16: 2026-07 | B16: caixa | C16: =SUMIFS(Lancamentos!L$2:L$3028,Lancamentos!J$2:J$3028,A16) -> 1267063.9 | D16: =SUMIFS(Lancamentos!L$2:L$3028,Lancamentos!J$2:J$3028,A16,Lancamentos!AC$2:AC$3028,"sim") -> 612228.57 | E16: =C16-D16 -> 654835.38 | F16: =D16+E16 -> 1267063.9 | G16: =F16-C16 -> 0 | H16: =IF(ABS(G16)<0.05,"sim","não") -> sim
A17: 2026-08 | B17: competencia | C17: =SUMIFS(Lancamentos!K$2:K$3028,Lancamentos!I$2:I$3028,A17) -> 921776.25 | D17: =SUMIFS(Lancamentos!K$2:K$3028,Lancamentos!I$2:I$3028,A17,Lancamentos!AC$2:AC$3028,"sim") -> 301348.09 | E17: =C17-D17 -> 620428.16 | F17: =D17+E17 -> 921776.25 | G17: =F17-C17 -> 0 | H17: =IF(ABS(G17)<0.05,"sim","não") -> sim
A18: 2026-08 | B18: caixa | C18: =SUMIFS(Lancamentos!L$2:L$3028,Lancamentos!J$2:J$3028,A18) -> 1253629.5 | D18: =SUMIFS(Lancamentos!L$2:L$3028,Lancamentos!J$2:J$3028,A18,Lancamentos!AC$2:AC$3028,"sim") -> 633474.23 | E18: =C18-D18 -> 620155.24 | F18: =D18+E18 -> 1253629.5 | G18: =F18-C18 -> 0 | H18: =IF(ABS(G18)<0.05,"sim","não") -> sim

Sheet Excluidos_por_motivo
A1: motivo | B1: valor_competencia | C1: pct_das_saidas
A2: Remuneração de sócios de capital | B2: 2768959.5 | C2: 0.3104075
A3: Repasse ao cliente (3.2.07 REPASSE DE OUTRAS RECEITAS; 2.6.04 sem movimento no período) | B3: 835346.5 | C3: 0.093644496
A4: Deduções / tributos sobre faturamento | B4: 543223.31 | C4: 0.060896733
A5: Despesas reembolsáveis de clientes | B5: 315147.79 | C5: 0.03532888
A6: Investimento / CAPEX | B6: 9727.61 | C6: 0.0010904902
A7: Adiantamento ou transferência (não é despesa operacional) | B7: 7600 | C7: 0.00085197959
A8: Dedução da receita | B8: 2000 | C8: 0.00022420516
A9: TOTAL EXCLUÍDO | B9: 4482004.7 | C9: 0.50244428
A10: OPEX | B10: 4438396.8 | C10: 0.49755572
A11: OPEX + EXCLUÍDOS | B11: 8920401.5 | C11: 1

Sheet Reembolsaveis_por_depto
A1: conta_numero | B1: plano_contas | C1: departamento | D1: qtd | E1: valor_competencia | F1: valor_caixa | G1: tratamento
A2: 5.16.06.000 | B2: OUTRAS DESPESAS REEMBOLSÁVEIS | C2: Conta Corrente Clientes | D2: 70 | E2: 26902.35 | F2: 26902.35 | G2: FORA do OPEX — reembolsável de cliente
A3: 5.6.02.000 | B3: CUSTAS JUDICIAIS | C3: Conta Corrente Clientes | D3: 77 | E3: 12167.08 | F3: 12167.08 | G3: FORA do OPEX — reembolsável de cliente
A4: 5.6.02.000 | B4: CUSTAS JUDICIAIS | C4: Cível | D4: 4 | E4: 8920.22 | F4: 8920.22 | G4: DENTRO do OPEX — Despesas Processuais, com flag
A5: 5.6.02.000 | B5: CUSTAS JUDICIAIS | C5: Insolvência | D5: 8 | E5: 5500.15 | F5: 5500.15 | G5: DENTRO do OPEX — Despesas Processuais, com flag
A6: 5.6.02.000 | B6: CUSTAS JUDICIAIS | C6: Recuperação de Crédito | D6: 22 | E6: 2584.03 | F6: 2584.03 | G6: DENTRO do OPEX — Despesas Processuais, com flag
A7: 5.6.02.000 | B7: CUSTAS JUDICIAIS | C7: Distressed Deals | D7: 16 | E7: 1827.99 | F7: 1827.99 | G7: DENTRO do OPEX — Despesas Processuais, com flag
A8: 5.6.02.000 | B8: CUSTAS JUDICIAIS | C8: Gustavo Bismarchi Motta | D8: 1 | E8: 192.1 | F8: 192.1 | G8: DENTRO do OPEX — Despesas Processuais, com flag
A9: 2.6.01.000 | B9: Custas | C9: — | D9: 0 | E9: 0 | F9: 0 | G9: sem lançamento no período
A10: 2.6.01.005 | B10: Correios jurídicos | C10: — | D10: 0 | E10: 0 | F10: 0 | G10: sem lançamento no período
A11: 2.6.03.000 | B11: Diligência | C11: — | D11: 0 | E11: 0 | F11: 0 | G11: sem lançamento no período
A12: 5.16.07.000 | B12: DESPESAS REEMBOLSÁVEIS - GUIAS | C12: — | D12: 0 | E12: 0 | F12: 0 | G12: sem lançamento no período

Sheet Controle_reembolso
A1: mes | B1: reembolsaveis_pagas_competencia | C1: reembolsos_recebidos_competencia | D1: saldo_competencia | E1: acumulado_competencia | F1: reembolsaveis_pagas_caixa | G1: reembolsos_recebidos_caixa | H1: saldo_caixa | I1: acumulado_caixa
